Workbook

Sheet Base de Tutores
E1: Controle de Tutores de Práticas
A2: CHAVE | B2: CHAVE GERENCIAMENTO | C2: CHAVE LOTAÇÃO CLASSIFICAÇÃO DE CURSOS | D2: CHAVE LOTAÇÃO | E2: CATEGORIA | F2: CURSOS | G2: POLO | H2: NOME DO TUTOR | I2: SITUAÇÃO | J2: INÍCIO | K2: WHATSAPP | L2: CHAPA | M2: E-MAIL INSTITUCIONAL | N2: CARGO RM | O2: CH SEMANAL | P2: DESLIGAMENTO | Q2: CONTRATO | R2: REGISTRO PROFISSIONAL | S2: Nº DE REGISTRO
A3: =IF(Tabela2[[#This Row],[SITUAÇÃO]]="Férias",CONCATENATE(Tabela2[[#This Row],[POLO]],Tabela2[[#This Row],[CURSOS]],Tabela2[[#This Row],[CATEGORIA]]),IF(Tabela2[[#This Row],[SITUAÇÃO]]="Ativo",CONCATENATE(Tabela2[[#This Row],[POLO]],Tabela2[[#This Row],[CURSOS]],Tabela2[[#This Row],[CATEGORIA]]),"desligado")) -> Abaetetuba/PAEMF-ISNENF-INS (Multidisciplinar II) | B3: =Tabela2[[#This Row],[CATEGORIA]]&Tabela2[[#This Row],[CURSOS]]&"LAP - "&Tabela2[[#This Row],[POLO]] -> ENF-INS (Multidisciplinar II)EMF-ISNLAP - Abaetetuba/PA | C3: =Tabela2[[#This Row],[CATEGORIA]]&Tabela2[[#This Row],[CURSOS]] -> ENF-INS (Multidisciplinar II)EMF-ISN | D3: =IF(Tabela2[[#This Row],[SITUAÇÃO]]<>"Demitido",CONCATENATE(Tabela2[[#This Row],[POLO]],Tabela2[[#This Row],[CURSOS]]),"Substituição") -> Abaetetuba/PAEMF-ISN | E3: ENF-INS (Multidisciplinar II) | F3: EMF-ISN | G3: Abaetetuba/PA | H3: Sandro Jose Santos Dos Santos | I3: =IFERROR(_xlfn.XLOOKUP(Tabela2[[#This Row],[CHAPA]],TUT.CONTROL!F:F,TUT.CONTROL!I:I),_xlfn.XLOOKUP(Tabela2[[#This Row],[CHAPA]],'REG.CONTROL'!F:F,'REG.CONTROL'!I:I)) -> Ativo | J3: =IFERROR(_xlfn.XLOOKUP(Tabela2[[#This Row],[NOME DO TUTOR]],TUT.CONTROL!C:C,TUT.CONTROL!G:G),"Atualizar") -> 45887 | K3: 91984011852 | L3: =IFERROR(_xlfn.XLOOKUP(Tabela2[[#This Row],[NOME DO TUTOR]],TUT.CONTROL!C:C,TUT.CONTROL!F:F),"Demitido") -> 1158000897 | M3: sandro.santos@tutorpratica.uniasselvi.com.br | N3: =IFERROR(_xlfn.XLOOKUP(Tabela2[[#This Row],[CHAPA]],TUT.CONTROL!F:F,TUT.CONTROL!H:H),_xlfn.XLOOKUP(Tabela2[[#This Row],[CHAPA]],'REG.CONTROL'!F:F,'REG.CONTROL'!H:H)) -> TUTOR DE PRATICA (UC_1749) | O3: =IFERROR(_xlfn.XLOOKUP(Tabela2[[#This Row],[NOME DO TUTOR]],TUT.CONTROL!C:C,TUT.CONTROL!K:K),"Demitido") -> 004:00 | P3: =IF(Tabela2[[#This Row],[SITUAÇÃO]]="Demitido",IFERROR(_xlfn.XLOOKUP(Tabela2[[#This Row],[CHAPA]],TUT.CONTROL!F:F,TUT.CONTROL!V:V),_xlfn.XLOOKUP(Tabela2[[#This Row],[CHAPA]],'REG.CONTROL'!F:F,'REG.CONTROL'!V:V)),"-") -> - | R3: COREN-PA | S3: 766981
A4: =IF(Tabela2[[#This Row],[SITUAÇÃO]]="Férias",CONCATENATE(Tabela2[[#This Row],[POLO]],Tabela2[[#This Row],[CURSOS]],Tabela2[[#This Row],[CATEGORIA]]),IF(Tabela2[[#This Row],[SITUAÇÃO]]="Ativo",CONCATENATE(Tabela2[[#This Row],[POLO]],Tabela2[[#This Row],[CURSOS]],Tabela2[[#This Row],[CATEGORIA]]),"desligado")) -> Acaraú/CEEMF-ISNENF-INS (Multidisciplinar II) | B4: =Tabela2[[#This Row],[CATEGORIA]]&Tabela2[[#This Row],[CURSOS]]&"LAP - "&Tabela2[[#This Row],[POLO]] -> ENF-INS (Multidisciplinar II)EMF-ISNLAP - Acaraú/CE | C4: =Tabela2[[#This Row],[CATEGORIA]]&Tabela2[[#This Row],[CURSOS]] -> ENF-INS (Multidisciplinar II)EMF-ISN | D4: =IF(Tabela2[[#This Row],[SITUAÇÃO]]<>"Demitido",CONCATENATE(Tabela2[[#This Row],[POLO]],Tabela2[[#This Row],[CURSOS]]),"Substituição") -> Acaraú/CEEMF-ISN | E4: ENF-INS (Multidisciplinar II) | F4: EMF-ISN | G4: Acaraú/CE | H4: Maria Suliana Machado Lima | I4: =IFERROR(_xlfn.XLOOKUP(Tabela2[[#This Row],[CHAPA]],TUT.CONTROL!F:F,TUT.CONTROL!I:I),_xlfn.XLOOKUP(Tabela2[[#This Row],[CHAPA]],'REG.CONTROL'!F:F,'REG.CONTROL'!I:I)) -> Ativo | J4: =IFERROR(_xlfn.XLOOKUP(Tabela2[[#This Row],[NOME DO TUTOR]],'REG.CONTROL'!C:C,'REG.CONTROL'!G:G),"Demitido") -> 44782 | K4: 88981943284 | L4: =IFERROR(_xlfn.XLOOKUP(Tabela2[[#This Row],[NOME DO TUTOR]],'REG.CONTROL'!C:C,'REG.CONTROL'!F:F),"Demitido") -> 1004010429 | M4: maria.lima@regentedepolo.uniasselvi.com.br | N4: =IFERROR(_xlfn.XLOOKUP(Tabela2[[#This Row],[CHAPA]],TUT.CONTROL!F:F,TUT.CONTROL!H:H),_xlfn.XLOOKUP(Tabela2[[#This Row],[CHAPA]],'REG.CONTROL'!F:F,'REG.CONTROL'!H:H)) -> PROFESSOR REGENTE DE POLO (UC_1744) | O4: =IFERROR(_xlfn.XLOOKUP(Tabela2[[#This Row],[NOME DO TUTOR]],'REGENTE CH'!A:A,'REGENTE CH'!C:C),"Atualizar") -> 008:00 | P4: =IF(Tabela2[[#This Row],[SITUAÇÃO]]="Demitido",IFERROR(_xlfn.XLOOKUP(Tabela2[[#This Row],[CHAPA]],TUT.CONTROL!F:F,TUT.CONTROL!V:V),_xlfn.XLOOKUP(Tabela2[[#This Row],[CHAPA]],'REG.CONTROL'!F:F,'REG.CONTROL'!V:V)),"-") -> - | Q4: OK | R4: COREN-CE | S4: 534.344
A5: =IF(Tabela2[[#This Row],[SITUAÇÃO]]="Férias",CONCATENATE(Tabela2[[#This Row],[POLO]],Tabela2[[#This Row],[CURSOS]],Tabela2[[#This Row],[CATEGORIA]]),IF(Tabela2[[#This Row],[SITUAÇÃO]]="Ativo",CONCATENATE(Tabela2[[#This Row],[POLO]],Tabela2[[#This Row],[CURSOS]],Tabela2[[#This Row],[CATEGORIA]]),"desligado")) -> Águas Belas/PEEMF-ISNENF-INS (Multidisciplinar II) | B5: =Tabela2[[#This Row],[CATEGORIA]]&Tabela2[[#This Row],[CURSOS]]&"LAP - "&Tabela2[[#This Row],[POLO]] -> ENF-INS (Multidisciplinar II)EMF-ISNLAP - Águas Belas/PE | C5: =Tabela2[[#This Row],[CATEGORIA]]&Tabela2[[#This Row],[CURSOS]] -> ENF-INS (Multidisciplinar II)EMF-ISN | D5: =IF(Tabela2[[#This Row],[SITUAÇÃO]]<>"Demitido",CONCATENATE(Tabela2[[#This Row],[POLO]],Tabela2[[#This Row],[CURSOS]]),"Substituição") -> Águas Belas/PEEMF-ISN | E5: ENF-INS (Multidisciplinar II) | F5: EMF-ISN | G5: Águas Belas/PE | H5: Jose Cicero Rosendo Da Silva Filho | I5: =IFERROR(_xlfn.XLOOKUP(Tabela2[[#This Row],[CHAPA]],TUT.CONTROL!F:F,TUT.CONTROL!I:I),_xlfn.XLOOKUP(Tabela2[[#This Row],[CHAPA]],'REG.CONTROL'!F:F,'REG.CONTROL'!I:I)) -> Ativo | J5: =IFERROR(_xlfn.XLOOKUP(Tabela2[[#This Row],[NOME DO TUTOR]],TUT.CONTROL!C:C,TUT.CONTROL!G:G),"Demitido") -> 45749 | K5: 87981132863 | L5: =IFERROR(_xlfn.XLOOKUP(Tabela2[[#This Row],[NOME DO TUTOR]],TUT.CONTROL!C:C,TUT.CONTROL!F:F),"Demitido") -> 1158000663 | M5: cicero.filho@tutorpratica.uniasselvi.com.br | N5: =IFERROR(_xlfn.XLOOKUP(Tabela2[[#This Row],[CHAPA]],TUT.CONTROL!F:F,TUT.CONTROL!H:H),_xlfn.XLOOKUP(Tabela2[[#This Row],[CHAPA]],'REG.CONTROL'!F:F,'REG.CONTROL'!H:H)) -> TUTOR DE PRATICA (UC_1749) | O5: =IFERROR(_xlfn.XLOOKUP(Tabela2[[#This Row],[NOME DO TUTOR]],TUT.CONTROL!C:C,TUT.CONTROL!K:K),"Demitido") -> 004:00 | P5: =IF(Tabela2[[#This Row],[SITUAÇÃO]]="Demitido",IFERROR(_xlfn.XLOOKUP(Tabela2[[#This Row],[CHAPA]],TUT.CONTROL!F:F,TUT.CONTROL!V:V),_xlfn.XLOOKUP(Tabela2[[#This Row],[CHAPA]],'REG.CONTROL'!F:F,'REG.CONTROL'!V:V)),"-") -> - | Q5: OK | R5: COREN-PE | S5: 373684
A6: =IF(Tabela2[[#This Row],[SITUAÇÃO]]="Férias",CONCATENATE(Tabela2[[#This Row],[POLO]],Tabela2[[#This Row],[CURSOS]],Tabela2[[#This Row],[CATEGORIA]]),IF(Tabela2[[#This Row],[SITUAÇÃO]]="Ativo",CONCATENATE(Tabela2[[#This Row],[POLO]],Tabela2[[#This Row],[CURSOS]],Tabela2[[#This Row],[CATEGORIA]]),"desligado")) -> Alenquer/PAEMF-ISNENF-INS (Multidisciplinar II) | B6: =Tabela2[[#This Row],[CATEGORIA]]&Tabela2[[#This Row],[CURSOS]]&"LAP - "&Tabela2[[#This Row],[POLO]] -> ENF-INS (Multidisciplinar II)EMF-ISNLAP - Alenquer/PA | C6: =Tabela2[[#This Row],[CATEGORIA]]&Tabela2[[#This Row],[CURSOS]] -> ENF-INS (Multidisciplinar II)EMF-ISN | D6: =IF(Tabela2[[#This Row],[SITUAÇÃO]]<>"Demitido",CONCATENATE(Tabela2[[#This Row],[POLO]],Tabela2[[#This Row],[CURSOS]]),"Substituição") -> Alenquer/PAEMF-ISN | E6: ENF-INS (Multidisciplinar II) | F6: EMF-ISN | G6: Alenquer/PA | H6: Ana Flavia Chaves De Souza | I6: =IFERROR(_xlfn.XLOOKUP(Tabela2[[#This Row],[CHAPA]],TUT.CONTROL!F:F,TUT.CONTROL!I:I),_xlfn.XLOOKUP(Tabela2[[#This Row],[CHAPA]],'REG.CONTROL'!F:F,'REG.CONTROL'!I:I)) -> Ativo | J6: =IFERROR(_xlfn.XLOOKUP(Tabela2[[#This Row],[NOME DO TUTOR]],'REG.CONTROL'!C:C,'REG.CONTROL'!G:G),"Demitido") -> 44986 | K6: 93 8420-9817 | L6: =IFERROR(_xlfn.XLOOKUP(Tabela2[[#This Row],[NOME DO TUTOR]],'REG.CONTROL'!C:C,'REG.CONTROL'!F:F),"Demitido") -> 1004011468 | M6: ana.souza@regentedepolo.uniasselvi.com.br | N6: =IFERROR(_xlfn.XLOOKUP(Tabela2[[#This Row],[CHAPA]],TUT.CONTROL!F:F,TUT.CONTROL!H:H),_xlfn.XLOOKUP(Tabela2[[#This Row],[CHAPA]],'REG.CONTROL'!F:F,'REG.CONTROL'!H:H)) -> PROFESSOR REGENTE DE POLO (UC_1744) | O6: =IFERROR(_xlfn.XLOOKUP(Tabela2[[#This Row],[NOME DO TUTOR]],'REGENTE CH'!A:A,'REGENTE CH'!C:C),"Atualizar") -> 004:00 | P6: =IF(Tabela2[[#This Row],[SITUAÇÃO]]="Demitido",IFERROR(_xlfn.XLOOKUP(Tabela2[[#This Row],[CHAPA]],TUT.CONTROL!F:F,TUT.CONTROL!V:V),_xlfn.XLOOKUP(Tabela2[[#This Row],[CHAPA]],'REG.CONTROL'!F:F,'REG.CONTROL'!V:V)),"-") -> - | Q6: OK | R6: COREN-PA | S6: 617498
A7: =IF(Tabela2[[#This Row],[SITUAÇÃO]]="Férias",CONCATENATE(Tabela2[[#This Row],[POLO]],Tabela2[[#This Row],[CURSOS]],Tabela2[[#This Row],[CATEGORIA]]),IF(Tabela2[[#This Row],[SITUAÇÃO]]="Ativo",CONCATENATE(Tabela2[[#This Row],[POLO]],Tabela2[[#This Row],[CURSOS]],Tabela2[[#This Row],[CATEGORIA]]),"desligado")) -> desligado | B7: =Tabela2[[#This Row],[CATEGORIA]]&Tabela2[[#This Row],[CURSOS]]&"LAP - "&Tabela2[[#This Row],[POLO]] -> ENF-INS (Multidisciplinar II)EMF-ISNLAP - Alta Floresta/MT | C7: =Tabela2[[#This Row],[CATEGORIA]]&Tabela2[[#This Row],[CURSOS]] -> ENF-INS (Multidisciplinar II)EMF-ISN | D7: =IF(Tabela2[[#This Row],[SITUAÇÃO]]<>"Demitido",CONCATENATE(Tabela2[[#This Row],[POLO]],Tabela2[[#This Row],[CURSOS]]),"Substituição") -> Substituição | E7: ENF-INS (Multidisciplinar II) | F7: EMF-ISN | G7: Alta Floresta/MT | H7: Fabia De Oliveira Carvalho | I7: =IFERROR(_xlfn.XLOOKUP(Tabela2[[#This Row],[CHAPA]],TUT.CONTROL!F:F,TUT.CONTROL!I:I),_xlfn.XLOOKUP(Tabela2[[#This Row],[CHAPA]],'REG.CONTROL'!F:F,'REG.CONTROL'!I:I)) -> Demitido | J7: =IFERROR(_xlfn.XLOOKUP(Tabela2[[#This Row],[NOME DO TUTOR]],TUT.CONTROL!C:C,TUT.CONTROL!G:G),"Demitido") -> 45754 | K7: 66996263876 | L7: =IFERROR(_xlfn.XLOOKUP(Tabela2[[#This Row],[NOME DO TUTOR]],TUT.CONTROL!C:C,TUT.CONTROL!F:F),"Demitido") -> 1158000694 | M7: fabia.carvalho@tutorpratica.uniasselvi.com.br | N7: =IFERROR(_xlfn.XLOOKUP(Tabela2[[#This Row],[CHAPA]],TUT.CONTROL!F:F,TUT.CONTROL!H:H),_xlfn.XLOOKUP(Tabela2[[#This Row],[CHAPA]],'REG.CONTROL'!F:F,'REG.CONTROL'!H:H)) -> TUTOR DE PRATICA (UC_1749) | O7: =IFERROR(_xlfn.XLOOKUP(Tabela2[[#This Row],[NOME DO TUTOR]],TUT.CONTROL!C:C,TUT.CONTROL!K:K),"Demitido") -> 004:00 | P7: =IF(Tabela2[[#This Row],[SITUAÇÃO]]="Demitido",IFERROR(_xlfn.XLOOKUP(Tabela2[[#This Row],[CHAPA]],TUT.CONTROL!F:F,TUT.CONTROL!V:V),_xlfn.XLOOKUP(Tabela2[[#This Row],[CHAPA]],'REG.CONTROL'!F:F,'REG.CONTROL'!V:V)),"-") -> 46064 | Q7: Desligado | R7: COREN-MT | S7: 725262
A8: =IF(Tabela2[[#This Row],[SITUAÇÃO]]="Férias",CONCATENATE(Tabela2[[#This Row],[POLO]],Tabela2[[#This Row],[CURSOS]],Tabela2[[#This Row],[CATEGORIA]]),IF(Tabela2[[#This Row],[SITUAÇÃO]]="Ativo",CONCATENATE(Tabela2[[#This Row],[POLO]],Tabela2[[#This Row],[CURSOS]],Tabela2[[#This Row],[CATEGORIA]]),"desligado")) -> Ananindeua/PA - Cidade NovaEMF-ISNENF-INS (Multidisciplinar II) | B8: =Tabela2[[#This Row],[CATEGORIA]]&Tabela2[[#This Row],[CURSOS]]&"LAP - "&Tabela2[[#This Row],[POLO]] -> ENF-INS (Multidisciplinar II)EMF-ISNLAP - Ananindeua/PA - Cidade Nova | C8: =Tabela2[[#This Row],[CATEGORIA]]&Tabela2[[#This Row],[CURSOS]] -> ENF-INS (Multidisciplinar II)EMF-ISN | D8: =IF(Tabela2[[#This Row],[SITUAÇÃO]]<>"Demitido",CONCATENATE(Tabela2[[#This Row],[POLO]],Tabela2[[#This Row],[CURSOS]]),"Substituição") -> Ananindeua/PA - Cidade NovaEMF-ISN | E8: ENF-INS (Multidisciplinar II) | F8: EMF-ISN | G8: Ananindeua/PA - Cidade Nova | H8: Alina Dariane Freitas Da Silva | I8: =IFERROR(_xlfn.XLOOKUP(Tabela2[[#This Row],[CHAPA]],TUT.CONTROL!F:F,TUT.CONTROL!I:I),_xlfn.XLOOKUP(Tabela2[[#This Row],[CHAPA]],'REG.CONTROL'!F:F,'REG.CONTROL'!I:I)) -> Ativo | J8: =IFERROR(_xlfn.XLOOKUP(Tabela2[[#This Row],[NOME DO TUTOR]],'REG.CONTROL'!C:C,'REG.CONTROL'!G:G),"Demitido") -> 44868 | K8: 91993395631 | L8: =IFERROR(_xlfn.XLOOKUP(Tabela2[[#This Row],[NOME DO TUTOR]],'REG.CONTROL'!C:C,'REG.CONTROL'!F:F),"Demitido") -> 1004011044 | M8: alina.silva@regentedepolo.uniasselvi.com.br | N8: =IFERROR(_xlfn.XLOOKUP(Tabela2[[#This Row],[CHAPA]],TUT.CONTROL!F:F,TUT.CONTROL!H:H),_xlfn.XLOOKUP(Tabela2[[#This Row],[CHAPA]],'REG.CONTROL'!F:F,'REG.CONTROL'!H:H)) -> PROFESSOR REGENTE DE POLO (UC_1744) | O8: =IFERROR(_xlfn.XLOOKUP(Tabela2[[#This Row],[NOME DO TUTOR]],'REGENTE CH'!A:A,'REGENTE CH'!C:C),"Atualizar") -> 012:00 | P8: =IF(Tabela2[[#This Row],[SITUAÇÃO]]="Demitido",IFERROR(_xlfn.XLOOKUP(Tabela2[[#This Row],[CHAPA]],TUT.CONTROL!F:F,TUT.CONTROL!V:V),_xlfn.XLOOKUP(Tabela2[[#This Row],[CHAPA]],'REG.CONTROL'!F:F,'REG.CONTROL'!V:V)),"-") -> - | Q8: OK | R8: COREN-PA | S8: 748382
A9: =IF(Tabela2[[#This Row],[SITUAÇÃO]]="Férias",CONCATENATE(Tabela2[[#This Row],[POLO]],Tabela2[[#This Row],[CURSOS]],Tabela2[[#This Row],[CATEGORIA]]),IF(Tabela2[[#This Row],[SITUAÇÃO]]="Ativo",CONCATENATE(Tabela2[[#This Row],[POLO]],Tabela2[[#This Row],[CURSOS]],Tabela2[[#This Row],[CATEGORIA]]),"desligado")) -> desligado | B9: =Tabela2[[#This Row],[CATEGORIA]]&Tabela2[[#This Row],[CURSOS]]&"LAP - "&Tabela2[[#This Row],[POLO]] -> ENF-INS (Multidisciplinar II)EMF-ISNLAP - Ananindeua/PA - Cidade Nova | C9: =Tabela2[[#This Row],[CATEGORIA]]&Tabela2[[#This Row],[CURSOS]] -> ENF-INS (Multidisciplinar II)EMF-ISN | D9: =IF(Tabela2[[#This Row],[SITUAÇÃO]]<>"Demitido",CONCATENATE(Tabela2[[#This Row],[POLO]],Tabela2[[#This Row],[CURSOS]]),"Substituição") -> Substituição | E9: ENF-INS (Multidisciplinar II) | F9: EMF-ISN | G9: Ananindeua/PA - Cidade Nova | H9: Gilmara Rodrigues Carvalho Costa | I9: =IFERROR(_xlfn.XLOOKUP(Tabela2[[#This Row],[CHAPA]],TUT.CONTROL!F:F,TUT.CONTROL!I:I),_xlfn.XLOOKUP(Tabela2[[#This Row],[CHAPA]],'REG.CONTROL'!F:F,'REG.CONTROL'!I:I)) -> Demitido | J9: =IFERROR(_xlfn.XLOOKUP(Tabela2[[#This Row],[NOME DO TUTOR]],TUT.CONTROL!C:C,TUT.CONTROL!G:G),"Demitido") -> 45887 | K9: 91992101489 | L9: =IFERROR(_xlfn.XLOOKUP(Tabela2[[#This Row],[NOME DO TUTOR]],TUT.CONTROL!C:C,TUT.CONTROL!F:F),"Demitido") -> 1158000891 | M9: gilmara.costa@tutorpratica.uniasselvi.com.br | N9: =IFERROR(_xlfn.XLOOKUP(Tabela2[[#This Row],[CHAPA]],TUT.CONTROL!F:F,TUT.CONTROL!H:H),_xlfn.XLOOKUP(Tabela2[[#This Row],[CHAPA]],'REG.CONTROL'!F:F,'REG.CONTROL'!H:H)) -> TUTOR DE PRATICA (UC_1749) | O9: =IFERROR(_xlfn.XLOOKUP(Tabela2[[#This Row],[NOME DO TUTOR]],TUT.CONTROL!C:C,TUT.CONTROL!K:K),"Demitido") -> 004:00 | P9: =IF(Tabela2[[#This Row],[SITUAÇÃO]]="Demitido",IFERROR(_xlfn.XLOOKUP(Tabela2[[#This Row],[CHAPA]],TUT.CONTROL!F:F,TUT.CONTROL!V:V),_xlfn.XLOOKUP(Tabela2[[#This Row],[CHAPA]],'REG.CONTROL'!F:F,'REG.CONTROL'!V:V)),"-") -> 45931 | Q9: Desligado
A10: =IF(Tabela2[[#This Row],[SITUAÇÃO]]="Férias",CONCATENATE(Tabela2[[#This Row],[POLO]],Tabela2[[#This Row],[CURSOS]],Tabela2[[#This Row],[CATEGORIA]]),IF(Tabela2[[#This Row],[SITUAÇÃO]]="Ativo",CONCATENATE(Tabela2[[#This Row],[POLO]],Tabela2[[#This Row],[CURSOS]],Tabela2[[#This Row],[CATEGORIA]]),"desligado")) -> Aquidauana/MSEMF-ISNENF-INS (Multidisciplinar II) | B10: =Tabela2[[#This Row],[CATEGORIA]]&Tabela2[[#This Row],[CURSOS]]&"LAP - "&Tabela2[[#This Row],[POLO]] -> ENF-INS (Multidisciplinar II)EMF-ISNLAP - Aquidauana/MS | C10: =Tabela2[[#This Row],[CATEGORIA]]&Tabela2[[#This Row],[CURSOS]] -> ENF-INS (Multidisciplinar II)EMF-ISN | D10: =IF(Tabela2[[#This Row],[SITUAÇÃO]]<>"Demitido",CONCATENATE(Tabela2[[#This Row],[POLO]],Tabela2[[#This Row],[CURSOS]]),"Substituição") -> Aquidauana/MSEMF-ISN | E10: ENF-INS (Multidisciplinar II) | F10: EMF-ISN | G10: Aquidauana/MS | H10: Erika Martins Leite | I10: =IFERROR(_xlfn.XLOOKUP(Tabela2[[#This Row],[CHAPA]],TUT.CONTROL!F:F,TUT.CONTROL!I:I),_xlfn.XLOOKUP(Tabela2[[#This Row],[CHAPA]],'REG.CONTROL'!F:F,'REG.CONTROL'!I:I)) -> Ativo | J10: =IFERROR(_xlfn.XLOOKUP(Tabela2[[#This Row],[NOME DO TUTOR]],'REG.CONTROL'!C:C,'REG.CONTROL'!G:G),"Demitido") -> 44783 | K10: 67992728254 | L10: =IFERROR(_xlfn.XLOOKUP(Tabela2[[#This Row],[NOME DO TUTOR]],'REG.CONTROL'!C:C,'REG.CONTROL'!F:F),"Demitido") -> 1004010463 | M10: erika.leite@regentedepolo.uniasselvi.com.br | N10: =IFERROR(_xlfn.XLOOKUP(Tabela2[[#This Row],[CHAPA]],TUT.CONTROL!F:F,TUT.CONTROL!H:H),_xlfn.XLOOKUP(Tabela2[[#This Row],[CHAPA]],'REG.CONTROL'!F:F,'REG.CONTROL'!H:H)) -> PROFESSOR REGENTE DE POLO (UC_1744) | O10: =IFERROR(_xlfn.XLOOKUP(Tabela2[[#This Row],[NOME DO TUTOR]],'REGENTE CH'!A:A,'REGENTE CH'!C:C),"Atualizar") -> 004:00 | P10: =IF(Tabela2[[#This Row],[SITUAÇÃO]]="Demitido",IFERROR(_xlfn.XLOOKUP(Tabela2[[#This Row],[CHAPA]],TUT.CONTROL!F:F,TUT.CONTROL!V:V),_xlfn.XLOOKUP(Tabela2[[#This Row],[CHAPA]],'REG.CONTROL'!F:F,'REG.CONTROL'!V:V)),"-") -> - | Q10: OK | R10: COREN-MS | S10: 483441
A11: =IF(Tabela2[[#This Row],[SITUAÇÃO]]="Férias",CONCATENATE(Tabela2[[#This Row],[POLO]],Tabela2[[#This Row],[CURSOS]],Tabela2[[#This Row],[CATEGORIA]]),IF(Tabela2[[#This Row],[SITUAÇÃO]]="Ativo",CONCATENATE(Tabela2[[#This Row],[POLO]],Tabela2[[#This Row],[CURSOS]],Tabela2[[#This Row],[CATEGORIA]]),"desligado")) -> Aracaju/SE - Ponto NovoEMF-ISNENF-INS (Multidisciplinar II) | B11: =Tabela2[[#This Row],[CATEGORIA]]&Tabela2[[#This Row],[CURSOS]]&"LAP - "&Tabela2[[#This Row],[POLO]] -> ENF-INS (Multidisciplinar II)EMF-ISNLAP - Aracaju/SE - Ponto Novo | C11: =Tabela2[[#This Row],[CATEGORIA]]&Tabela2[[#This Row],[CURSOS]] -> ENF-INS (Multidisciplinar II)EMF-ISN | D11: =IF(Tabela2[[#This Row],[SITUAÇÃO]]<>"Demitido",CONCATENATE(Tabela2[[#This Row],[POLO]],Tabela2[[#This Row],[CURSOS]]),"Substituição") -> Aracaju/SE - Ponto NovoEMF-ISN | E11: ENF-INS (Multidisciplinar II) | F11: EMF-ISN | G11: Aracaju/SE - Ponto Novo | H11: Caio Guilherme Santos Morais Oliveira | I11: =IFERROR(_xlfn.XLOOKUP(Tabela2[[#This Row],[CHAPA]],TUT.CONTROL!F:F,TUT.CONTROL!I:I),_xlfn.XLOOKUP(Tabela2[[#This Row],[CHAPA]],'REG.CONTROL'!F:F,'REG.CONTROL'!I:I)) -> Ativo | J11: =IFERROR(_xlfn.XLOOKUP(Tabela2[[#This Row],[NOME DO TUTOR]],TUT.CONTROL!C:C,TUT.CONTROL!G:G),"Demitido") -> 45728 | K11: 79998583631 | L11: =IFERROR(_xlfn.XLOOKUP(Tabela2[[#This Row],[NOME DO TUTOR]],TUT.CONTROL!C:C,TUT.CONTROL!F:F),"Demitido") -> 1158000547 | M11: caio.oliveira@tutorpratica.uniasselvi.com.br | N11: =IFERROR(_xlfn.XLOOKUP(Tabela2[[#This Row],[CHAPA]],TUT.CONTROL!F:F,TUT.CONTROL!H:H),_xlfn.XLOOKUP(Tabela2[[#This Row],[CHAPA]],'REG.CONTROL'!F:F,'REG.CONTROL'!H:H)) -> TUTOR DE PRATICA (UC_1749) | O11: =IFERROR(_xlfn.XLOOKUP(Tabela2[[#This Row],[NOME DO TUTOR]],TUT.CONTROL!C:C,TUT.CONTROL!K:K),"Demitido") -> 004:00 | P11: =IF(Tabela2[[#This Row],[SITUAÇÃO]]="Demitido",IFERROR(_xlfn.XLOOKUP(Tabela2[[#This Row],[CHAPA]],TUT.CONTROL!F:F,TUT.CONTROL!V:V),_xlfn.XLOOKUP(Tabela2[[#This Row],[CHAPA]],'REG.CONTROL'!F:F,'REG.CONTROL'!V:V)),"-") -> - | Q11: OK | R11: COREN-SE | S11: 770627
A12: =IF(Tabela2[[#This Row],[SITUAÇÃO]]="Férias",CONCATENATE(Tabela2[[#This Row],[POLO]],Tabela2[[#This Row],[CURSOS]],Tabela2[[#This Row],[CATEGORIA]]),IF(Tabela2[[#This Row],[SITUAÇÃO]]="Ativo",CONCATENATE(Tabela2[[#This Row],[POLO]],Tabela2[[#This Row],[CURSOS]],Tabela2[[#This Row],[CATEGORIA]]),"desligado")) -> Aracati/CEEMF-ISNENF-INS (Multidisciplinar II) | B12: =Tabela2[[#This Row],[CATEGORIA]]&Tabela2[[#This Row],[CURSOS]]&"LAP - "&Tabela2[[#This Row],[POLO]] -> ENF-INS (Multidisciplinar II)EMF-ISNLAP - Aracati/CE | C12: =Tabela2[[#This Row],[CATEGORIA]]&Tabela2[[#This Row],[CURSOS]] -> ENF-INS (Multidisciplinar II)EMF-ISN | D12: =IF(Tabela2[[#This Row],[SITUAÇÃO]]<>"Demitido",CONCATENATE(Tabela2[[#This Row],[POLO]],Tabela2[[#This Row],[CURSOS]]),"Substituição") -> Aracati/CEEMF-ISN | E12: ENF-INS (Multidisciplinar II) | F12: EMF-ISN | G12: Aracati/CE | H12: Debora Ferreira Dos Anjos | I12: =IFERROR(_xlfn.XLOOKUP(Tabela2[[#This Row],[CHAPA]],TUT.CONTROL!F:F,TUT.CONTROL!I:I),_xlfn.XLOOKUP(Tabela2[[#This Row],[CHAPA]],'REG.CONTROL'!F:F,'REG.CONTROL'!I:I)) -> Ativo | J12: =IFERROR(_xlfn.XLOOKUP(Tabela2[[#This Row],[NOME DO TUTOR]],TUT.CONTROL!C:C,TUT.CONTROL!G:G),"Demitido") -> 45721 | K12: 88997292003 | L12: =IFERROR(_xlfn.XLOOKUP(Tabela2[[#This Row],[NOME DO TUTOR]],TUT.CONTROL!C:C,TUT.CONTROL!F:F),"Demitido") -> 1158000534 | M12: debora.anjos@tutorpratica.uniasselvi.com.br | N12: =IFERROR(_xlfn.XLOOKUP(Tabela2[[#This Row],[CHAPA]],TUT.CONTROL!F:F,TUT.CONTROL!H:H),_xlfn.XLOOKUP(Tabela2[[#This Row],[CHAPA]],'REG.CONTROL'!F:F,'REG.CONTROL'!H:H)) -> TUTOR DE PRATICA (UC_1749) | O12: =IFERROR(_xlfn.XLOOKUP(Tabela2[[#This Row],[NOME DO TUTOR]],TUT.CONTROL!C:C,TUT.CONTROL!K:K),"Demitido") -> 004:00 | P12: =IF(Tabela2[[#This Row],[SITUAÇÃO]]="Demitido",IFERROR(_xlfn.XLOOKUP(Tabela2[[#This Row],[CHAPA]],TUT.CONTROL!F:F,TUT.CONTROL!V:V),_xlfn.XLOOKUP(Tabela2[[#This Row],[CHAPA]],'REG.CONTROL'!F:F,'REG.CONTROL'!V:V)),"-") -> - | Q12: OK | R12: COREN-CE | S12: 580957
A13: =IF(Tabela2[[#This Row],[SITUAÇÃO]]="Férias",CONCATENATE(Tabela2[[#This Row],[POLO]],Tabela2[[#This Row],[CURSOS]],Tabela2[[#This Row],[CATEGORIA]]),IF(Tabela2[[#This Row],[SITUAÇÃO]]="Ativo",CONCATENATE(Tabela2[[#This Row],[POLO]],Tabela2[[#This Row],[CURSOS]],Tabela2[[#This Row],[CATEGORIA]]),"desligado")) -> Araguaína/TOEMF-ISNENF-INS (Multidisciplinar II) | B13: =Tabela2[[#This Row],[CATEGORIA]]&Tabela2[[#This Row],[CURSOS]]&"LAP - "&Tabela2[[#This Row],[POLO]] -> ENF-INS (Multidisciplinar II)EMF-ISNLAP - Araguaína/TO | C13: =Tabela2[[#This Row],[CATEGORIA]]&Tabela2[[#This Row],[CURSOS]] -> ENF-INS (Multidisciplinar II)EMF-ISN | D13: =IF(Tabela2[[#This Row],[SITUAÇÃO]]<>"Demitido",CONCATENATE(Tabela2[[#This Row],[POLO]],Tabela2[[#This Row],[CURSOS]]),"Substituição") -> Araguaína/TOEMF-ISN | E13: ENF-INS (Multidisciplinar II) | F13: EMF-ISN | G13: Araguaína/TO | H13: Vanessa De Oliveira Menezes | I13: =IFERROR(_xlfn.XLOOKUP(Tabela2[[#This Row],[CHAPA]],TUT.CONTROL!F:F,TUT.CONTROL!I:I),_xlfn.XLOOKUP(Tabela2[[#This Row],[CHAPA]],'REG.CONTROL'!F:F,'REG.CONTROL'!I:I)) -> Ativo | J13: =IFERROR(_xlfn.XLOOKUP(Tabela2[[#This Row],[NOME DO TUTOR]],TUT.CONTROL!C:C,TUT.CONTROL!G:G),"Demitido") -> 45733 | K13: 63992070009 | L13: =IFERROR(_xlfn.XLOOKUP(Tabela2[[#This Row],[NOME DO TUTOR]],TUT.CONTROL!C:C,TUT.CONTROL!F:F),"Demitido") -> 1158000556 | M13: vanessa.menezes@tutorpratica.uniasselvi.com.br | N13: =IFERROR(_xlfn.XLOOKUP(Tabela2[[#This Row],[CHAPA]],TUT.CONTROL!F:F,TUT.CONTROL!H:H),_xlfn.XLOOKUP(Tabela2[[#This Row],[CHAPA]],'REG.CONTROL'!F:F,'REG.CONTROL'!H:H)) -> TUTOR DE PRATICA (UC_1749) | O13: =IFERROR(_xlfn.XLOOKUP(Tabela2[[#This Row],[NOME DO TUTOR]],TUT.CONTROL!C:C,TUT.CONTROL!K:K),"Demitido") -> 004:00 | P13: =IF(Tabela2[[#This Row],[SITUAÇÃO]]="Demitido",IFERROR(_xlfn.XLOOKUP(Tabela2[[#This Row],[CHAPA]],TUT.CONTROL!F:F,TUT.CONTROL!V:V),_xlfn.XLOOKUP(Tabela2[[#This Row],[CHAPA]],'REG.CONTROL'!F:F,'REG.CONTROL'!V:V)),"-") -> - | Q13: OK | R13: COREN-TO | S13: 839296
A14: =IF(Tabela2[[#This Row],[SITUAÇÃO]]="Férias",CONCATENATE(Tabela2[[#This Row],[POLO]],Tabela2[[#This Row],[CURSOS]],Tabela2[[#This Row],[CATEGORIA]]),IF(Tabela2[[#This Row],[SITUAÇÃO]]="Ativo",CONCATENATE(Tabela2[[#This Row],[POLO]],Tabela2[[#This Row],[CURSOS]],Tabela2[[#This Row],[CATEGORIA]]),"desligado")) -> Aripuanã/MTEMF-ISNENF-INS (Multidisciplinar II) | B14: =Tabela2[[#This Row],[CATEGORIA]]&Tabela2[[#This Row],[CURSOS]]&"LAP - "&Tabela2[[#This Row],[POLO]] -> ENF-INS (Multidisciplinar II)EMF-ISNLAP - Aripuanã/MT | C14: =Tabela2[[#This Row],[CATEGORIA]]&Tabela2[[#This Row],[CURSOS]] -> ENF-INS (Multidisciplinar II)EMF-ISN | D14: =IF(Tabela2[[#This Row],[SITUAÇÃO]]<>"Demitido",CONCATENATE(Tabela2[[#This Row],[POLO]],Tabela2[[#This Row],[CURSOS]]),"Substituição") -> Aripuanã/MTEMF-ISN | E14: ENF-INS (Multidisciplinar II) | F14: EMF-ISN | G14: Aripuanã/MT | H14: Tarcilio Jose Salles Sampaio Neto | I14: =IFERROR(_xlfn.XLOOKUP(Tabela2[[#This Row],[CHAPA]],TUT.CONTROL!F:F,TUT.CONTROL!I:I),_xlfn.XLOOKUP(Tabela2[[#This Row],[CHAPA]],'REG.CONTROL'!F:F,'REG.CONTROL'!I:I)) -> Ativo | J14: =IFERROR(_xlfn.XLOOKUP(Tabela2[[#This Row],[NOME DO TUTOR]],TUT.CONTROL!C:C,TUT.CONTROL!G:G),"Demitido") -> 45798 | K14: 69999789575 | L14: =IFERROR(_xlfn.XLOOKUP(Tabela2[[#This Row],[NOME DO TUTOR]],TUT.CONTROL!C:C,TUT.CONTROL!F:F),"Demitido") -> 1158000708 | M14: tarcilio.neto@tutorpratica.uniasselvi.com.br | N14: =IFERROR(_xlfn.XLOOKUP(Tabela2[[#This Row],[CHAPA]],TUT.CONTROL!F:F,TUT.CONTROL!H:H),_xlfn.XLOOKUP(Tabela2[[#This Row],[CHAPA]],'REG.CONTROL'!F:F,'REG.CONTROL'!H:H)) -> TUTOR DE PRATICA (UC_1749) | O14: =IFERROR(_xlfn.XLOOKUP(Tabela2[[#This Row],[NOME DO TUTOR]],TUT.CONTROL!C:C,TUT.CONTROL!K:K),"Demitido") -> 004:00 | P14: =IF(Tabela2[[#This Row],[SITUAÇÃO]]="Demitido",IFERROR(_xlfn.XLOOKUP(Tabela2[[#This Row],[CHAPA]],TUT.CONTROL!F:F,TUT.CONTROL!V:V),_xlfn.XLOOKUP(Tabela2[[#This Row],[CHAPA]],'REG.CONTROL'!F:F,'REG.CONTROL'!V:V)),"-") -> -
A15: =IF(Tabela2[[#This Row],[SITUAÇÃO]]="Férias",CONCATENATE(Tabela2[[#This Row],[POLO]],Tabela2[[#This Row],[CURSOS]],Tabela2[[#This Row],[CATEGORIA]]),IF(Tabela2[[#This Row],[SITUAÇÃO]]="Ativo",CONCATENATE(Tabela2[[#This Row],[POLO]],Tabela2[[#This Row],[CURSOS]],Tabela2[[#This Row],[CATEGORIA]]),"desligado")) -> Assú/RNEMF-ISNENF-INS (Multidisciplinar II) | B15: =Tabela2[[#This Row],[CATEGORIA]]&Tabela2[[#This Row],[CURSOS]]&"LAP - "&Tabela2[[#This Row],[POLO]] -> ENF-INS (Multidisciplinar II)EMF-ISNLAP - Assú/RN | C15: =Tabela2[[#This Row],[CATEGORIA]]&Tabela2[[#This Row],[CURSOS]] -> ENF-INS (Multidisciplinar II)EMF-ISN | D15: =IF(Tabela2[[#This Row],[SITUAÇÃO]]<>"Demitido",CONCATENATE(Tabela2[[#This Row],[POLO]],Tabela2[[#This Row],[CURSOS]]),"Substituição") -> Assú/RNEMF-ISN | E15: ENF-INS (Multidisciplinar II) | F15: EMF-ISN | G15: Assú/RN | H15: Romulo Freire Pinto | I15: =IFERROR(_xlfn.XLOOKUP(Tabela2[[#This Row],[CHAPA]],TUT.CONTROL!F:F,TUT.CONTROL!I:I),_xlfn.XLOOKUP(Tabela2[[#This Row],[CHAPA]],'REG.CONTROL'!F:F,'REG.CONTROL'!I:I)) -> Ativo | J15: =IFERROR(_xlfn.XLOOKUP(Tabela2[[#This Row],[NOME DO TUTOR]],TUT.CONTROL!C:C,TUT.CONTROL!G:G),"Demitido") -> 45754 | K15: 84999929870 | L15: =IFERROR(_xlfn.XLOOKUP(Tabela2[[#This Row],[NOME DO TUTOR]],TUT.CONTROL!C:C,TUT.CONTROL!F:F),"Demitido") -> 1158000688 | M15: romulo.pinto@tutorpratica.uniasselvi.com.br | N15: =IFERROR(_xlfn.XLOOKUP(Tabela2[[#This Row],[CHAPA]],TUT.CONTROL!F:F,TUT.CONTROL!H:H),_xlfn.XLOOKUP(Tabela2[[#This Row],[CHAPA]],'REG.CONTROL'!F:F,'REG.CONTROL'!H:H)) -> TUTOR DE PRATICA (UC_1749) | O15: =IFERROR(_xlfn.XLOOKUP(Tabela2[[#This Row],[NOME DO TUTOR]],TUT.CONTROL!C:C,TUT.CONTROL!K:K),"Demitido") -> 004:00 | P15: =IF(Tabela2[[#This Row],[SITUAÇÃO]]="Demitido",IFERROR(_xlfn.XLOOKUP(Tabela2[[#This Row],[CHAPA]],TUT.CONTROL!F:F,TUT.CONTROL!V:V),_xlfn.XLOOKUP(Tabela2[[#This Row],[CHAPA]],'REG.CONTROL'!F:F,'REG.CONTROL'!V:V)),"-") -> - | Q15: OK | R15: COREN-RN | S15: 241411
A16: =IF(Tabela2[[#This Row],[SITUAÇÃO]]="Férias",CONCATENATE(Tabela2[[#This Row],[POLO]],Tabela2[[#This Row],[CURSOS]],Tabela2[[#This Row],[CATEGORIA]]),IF(Tabela2[[#This Row],[SITUAÇÃO]]="Ativo",CONCATENATE(Tabela2[[#This Row],[POLO]],Tabela2[[#This Row],[CURSOS]],Tabela2[[#This Row],[CATEGORIA]]),"desligado")) -> Avaré/SPEMF-ISNENF-INS (Multidisciplinar II) | B16: =Tabela2[[#This Row],[CATEGORIA]]&Tabela2[[#This Row],[CURSOS]]&"LAP - "&Tabela2[[#This Row],[POLO]] -> ENF-INS (Multidisciplinar II)EMF-ISNLAP - Avaré/SP | C16: =Tabela2[[#This Row],[CATEGORIA]]&Tabela2[[#This Row],[CURSOS]] -> ENF-INS (Multidisciplinar II)EMF-ISN | D16: =IF(Tabela2[[#This Row],[SITUAÇÃO]]<>"Demitido",CONCATENATE(Tabela2[[#This Row],[POLO]],Tabela2[[#This Row],[CURSOS]]),"Substituição") -> Avaré/SPEMF-ISN | E16: ENF-INS (Multidisciplinar II) | F16: EMF-ISN | G16: Avaré/SP | H16: Larissa Brandolin Ventura | I16: =IFERROR(_xlfn.XLOOKUP(Tabela2[[#This Row],[CHAPA]],TUT.CONTROL!F:F,TUT.CONTROL!I:I),_xlfn.XLOOKUP(Tabela2[[#This Row],[CHAPA]],'REG.CONTROL'!F:F,'REG.CONTROL'!I:I)) -> Ativo | J16: =IFERROR(_xlfn.XLOOKUP(Tabela2[[#This Row],[NOME DO TUTOR]],TUT.CONTROL!C:C,TUT.CONTROL!G:G),"Demitido") -> 45749 | K16: 14996292308 | L16: =IFERROR(_xlfn.XLOOKUP(Tabela2[[#This Row],[NOME DO TUTOR]],TUT.CONTROL!C:C,TUT.CONTROL!F:F),"Demitido") -> 1158000671 | M16: larissa.silva@tutorpratica.uniasselvi.com.br | N16: =IFERROR(_xlfn.XLOOKUP(Tabela2[[#This Row],[CHAPA]],TUT.CONTROL!F:F,TUT.CONTROL!H:H),_xlfn.XLOOKUP(Tabela2[[#This Row],[CHAPA]],'REG.CONTROL'!F:F,'REG.CONTROL'!H:H)) -> TUTOR DE PRATICA (UC_1749) | O16: =IFERROR(_xlfn.XLOOKUP(Tabela2[[#This Row],[NOME DO TUTOR]],TUT.CONTROL!C:C,TUT.CONTROL!K:K),"Demitido") -> 004:00 | P16: =IF(Tabela2[[#This Row],[SITUAÇÃO]]="Demitido",IFERROR(_xlfn.XLOOKUP(Tabela2[[#This Row],[CHAPA]],TUT.CONTROL!F:F,TUT.CONTROL!V:V),_xlfn.XLOOKUP(Tabela2[[#This Row],[CHAPA]],'REG.CONTROL'!F:F,'REG.CONTROL'!V:V)),"-") -> - | Q16: OK | R16: COREN-SP | S16: 753858
A17: =IF(Tabela2[[#This Row],[SITUAÇÃO]]="Férias",CONCATENATE(Tabela2[[#This Row],[POLO]],Tabela2[[#This Row],[CURSOS]],Tabela2[[#This Row],[CATEGORIA]]),IF(Tabela2[[#This Row],[SITUAÇÃO]]="Ativo",CONCATENATE(Tabela2[[#This Row],[POLO]],Tabela2[[#This Row],[CURSOS]],Tabela2[[#This Row],[CATEGORIA]]),"desligado")) -> Barcelos/AMEMF-ISNENF-INS (Multidisciplinar II) | B17: =Tabela2[[#This Row],[CATEGORIA]]&Tabela2[[#This Row],[CURSOS]]&"LAP - "&Tabela2[[#This Row],[POLO]] -> ENF-INS (Multidisciplinar II)EMF-ISNLAP - Barcelos/AM | C17: =Tabela2[[#This Row],[CATEGORIA]]&Tabela2[[#This Row],[CURSOS]] -> ENF-INS (Multidisciplinar II)EMF-ISN | D17: =IF(Tabela2[[#This Row],[SITUAÇÃO]]<>"Demitido",CONCATENATE(Tabela2[[#This Row],[POLO]],Tabela2[[#This Row],[CURSOS]]),"Substituição") -> Barcelos/AMEMF-ISN | E17: ENF-INS (Multidisciplinar II) | F17: EMF-ISN | G17: Barcelos/AM | H17: Priscila Ferreira De Sousa | I17: =IFERROR(_xlfn.XLOOKUP(Tabela2[[#This Row],[CHAPA]],TUT.CONTROL!F:F,TUT.CONTROL!I:I),_xlfn.XLOOKUP(Tabela2[[#This Row],[CHAPA]],'REG.CONTROL'!F:F,'REG.CONTROL'!I:I)) -> Ativo | J17: =IFERROR(_xlfn.XLOOKUP(Tabela2[[#This Row],[NOME DO TUTOR]],TUT.CONTROL!C:C,TUT.CONTROL!G:G),"Demitido") -> 45971 | K17: 99988252370 | L17: =IFERROR(_xlfn.XLOOKUP(Tabela2[[#This Row],[NOME DO TUTOR]],TUT.CONTROL!C:C,TUT.CONTROL!F:F),"Demitido") -> 1158001060 | M17: priscila.sousa@tutorpratica.uniasselvi.com.br | N17: =IFERROR(_xlfn.XLOOKUP(Tabela2[[#This Row],[CHAPA]],TUT.CONTROL!F:F,TUT.CONTROL!H:H),_xlfn.XLOOKUP(Tabela2[[#This Row],[CHAPA]],'REG.CONTROL'!F:F,'REG.CONTROL'!H:H)) -> TUTOR DE PRATICA (UC_1749) | O17: =IFERROR(_xlfn.XLOOKUP(Tabela2[[#This Row],[NOME DO TUTOR]],TUT.CONTROL!C:C,TUT.CONTROL!K:K),"Demitido") -> 004:00 | P17: =IF(Tabela2[[#This Row],[SITUAÇÃO]]="Demitido",IFERROR(_xlfn.XLOOKUP(Tabela2[[#This Row],[CHAPA]],TUT.CONTROL!F:F,TUT.CONTROL!V:V),_xlfn.XLOOKUP(Tabela2[[#This Row],[CHAPA]],'REG.CONTROL'!F:F,'REG.CONTROL'!V:V)),"-") -> - | Q17: OK
A18: =IF(Tabela2[[#This Row],[SITUAÇÃO]]="Férias",CONCATENATE(Tabela2[[#This Row],[POLO]],Tabela2[[#This Row],[CURSOS]],Tabela2[[#This Row],[CATEGORIA]]),IF(Tabela2[[#This Row],[SITUAÇÃO]]="Ativo",CONCATENATE(Tabela2[[#This Row],[POLO]],Tabela2[[#This Row],[CURSOS]],Tabela2[[#This Row],[CATEGORIA]]),"desligado")) -> Barra do Garças/MTEMF-ISNENF-INS (Multidisciplinar II) | B18: =Tabela2[[#This Row],[CATEGORIA]]&Tabela2[[#This Row],[CURSOS]]&"LAP - "&Tabela2[[#This Row],[POLO]] -> ENF-INS (Multidisciplinar II)EMF-ISNLAP - Barra do Garças/MT | C18: =Tabela2[[#This Row],[CATEGORIA]]&Tabela2[[#This Row],[CURSOS]] -> ENF-INS (Multidisciplinar II)EMF-ISN | D18: =IF(Tabela2[[#This Row],[SITUAÇÃO]]<>"Demitido",CONCATENATE(Tabela2[[#This Row],[POLO]],Tabela2[[#This Row],[CURSOS]]),"Substituição") -> Barra do Garças/MTEMF-ISN | E18: ENF-INS (Multidisciplinar II) | F18: EMF-ISN | G18: Barra do Garças/MT | H18: Gabriella Ribeiro Sousa | I18: =IFERROR(_xlfn.XLOOKUP(Tabela2[[#This Row],[CHAPA]],TUT.CONTROL!F:F,TUT.CONTROL!I:I),_xlfn.XLOOKUP(Tabela2[[#This Row],[CHAPA]],'REG.CONTROL'!F:F,'REG.CONTROL'!I:I)) -> Ativo | J18: =IFERROR(_xlfn.XLOOKUP(Tabela2[[#This Row],[NOME DO TUTOR]],TUT.CONTROL!C:C,TUT.CONTROL!G:G),"Demitido") -> 45735 | K18: 66992246865 | L18: =IFERROR(_xlfn.XLOOKUP(Tabela2[[#This Row],[NOME DO TUTOR]],TUT.CONTROL!C:C,TUT.CONTROL!F:F),"Demitido") -> 1158000575 | M18: gabriella.sousa@tutorpratica.uniasselvi.com.br | N18: =IFERROR(_xlfn.XLOOKUP(Tabela2[[#This Row],[CHAPA]],TUT.CONTROL!F:F,TUT.CONTROL!H:H),_xlfn.XLOOKUP(Tabela2[[#This Row],[CHAPA]],'REG.CONTROL'!F:F,'REG.CONTROL'!H:H)) -> TUTOR DE PRATICA (UC_1749) | O18: =IFERROR(_xlfn.XLOOKUP(Tabela2[[#This Row],[NOME DO TUTOR]],TUT.CONTROL!C:C,TUT.CONTROL!K:K),"Demitido") -> 004:00 | P18: =IF(Tabela2[[#This Row],[SITUAÇÃO]]="Demitido",IFERROR(_xlfn.XLOOKUP(Tabela2[[#This Row],[CHAPA]],TUT.CONTROL!F:F,TUT.CONTROL!V:V),_xlfn.XLOOKUP(Tabela2[[#This Row],[CHAPA]],'REG.CONTROL'!F:F,'REG.CONTROL'!V:V)),"-") -> - | Q18: OK | R18: COREN-MT | S18: 000.710.572
A19: =IF(Tabela2[[#This Row],[SITUAÇÃO]]="Férias",CONCATENATE(Tabela2[[#This Row],[POLO]],Tabela2[[#This Row],[CURSOS]],Tabela2[[#This Row],[CATEGORIA]]),IF(Tabela2[[#This Row],[SITUAÇÃO]]="Ativo",CONCATENATE(Tabela2[[#This Row],[POLO]],Tabela2[[#This Row],[CURSOS]],Tabela2[[#This Row],[CATEGORIA]]),"desligado")) -> Barreirinhas/MAEMF-ISNENF-INS (Multidisciplinar II) | B19: =Tabela2[[#This Row],[CATEGORIA]]&Tabela2[[#This Row],[CURSOS]]&"LAP - "&Tabela2[[#This Row],[POLO]] -> ENF-INS (Multidisciplinar II)EMF-ISNLAP - Barreirinhas/MA | C19: =Tabela2[[#This Row],[CATEGORIA]]&Tabela2[[#This Row],[CURSOS]] -> ENF-INS (Multidisciplinar II)EMF-ISN | D19: =IF(Tabela2[[#This Row],[SITUAÇÃO]]<>"Demitido",CONCATENATE(Tabela2[[#This Row],[POLO]],Tabela2[[#This Row],[CURSOS]]),"Substituição") -> Barreirinhas/MAEMF-ISN | E19: ENF-INS (Multidisciplinar II) | F19: EMF-ISN | G19: Barreirinhas/MA | H19: Hozana De Almeida Evangelista | I19: =IFERROR(_xlfn.XLOOKUP(Tabela2[[#This Row],[CHAPA]],TUT.CONTROL!F:F,TUT.CONTROL!I:I),_xlfn.XLOOKUP(Tabela2[[#This Row],[CHAPA]],'REG.CONTROL'!F:F,'REG.CONTROL'!I:I)) -> Ativo | J19: =IFERROR(_xlfn.XLOOKUP(Tabela2[[#This Row],[NOME DO TUTOR]],TUT.CONTROL!C:C,TUT.CONTROL!G:G),"Demitido") -> 45733 | K19: 98988183281 | L19: =IFERROR(_xlfn.XLOOKUP(Tabela2[[#This Row],[NOME DO TUTOR]],TUT.CONTROL!C:C,TUT.CONTROL!F:F),"Demitido") -> 1158000553 | M19: hozana.evangelista@tutorpratica.uniasselvi.com.br | N19: =IFERROR(_xlfn.XLOOKUP(Tabela2[[#This Row],[CHAPA]],TUT.CONTROL!F:F,TUT.CONTROL!H:H),_xlfn.XLOOKUP(Tabela2[[#This Row],[CHAPA]],'REG.CONTROL'!F:F,'REG.CONTROL'!H:H)) -> TUTOR DE PRATICA (UC_1749) | O19: =IFERROR(_xlfn.XLOOKUP(Tabela2[[#This Row],[NOME DO TUTOR]],TUT.CONTROL!C:C,TUT.CONTROL!K:K),"Demitido") -> 004:00 | P19: =IF(Tabela2[[#This Row],[SITUAÇÃO]]="Demitido",IFERROR(_xlfn.XLOOKUP(Tabela2[[#This Row],[CHAPA]],TUT.CONTROL!F:F,TUT.CONTROL!V:V),_xlfn.XLOOKUP(Tabela2[[#This Row],[CHAPA]],'REG.CONTROL'!F:F,'REG.CONTROL'!V:V)),"-") -> - | Q19: OK | R19: COREN-MA | S19: 330425
A20: =IF(Tabela2[[#This Row],[SITUAÇÃO]]="Férias",CONCATENATE(Tabela2[[#This Row],[POLO]],Tabela2[[#This Row],[CURSOS]],Tabela2[[#This Row],[CATEGORIA]]),IF(Tabela2[[#This Row],[SITUAÇÃO]]="Ativo",CONCATENATE(Tabela2[[#This Row],[POLO]],Tabela2[[#This Row],[CURSOS]],Tabela2[[#This Row],[CATEGORIA]]),"desligado")) -> Baturité/CEEMF-ISNENF-INS (Multidisciplinar II) | B20: =Tabela2[[#This Row],[CATEGORIA]]&Tabela2[[#This Row],[CURSOS]]&"LAP - "&Tabela2[[#This Row],[POLO]] -> ENF-INS (Multidisciplinar II)EMF-ISNLAP - Baturité/CE | C20: =Tabela2[[#This Row],[CATEGORIA]]&Tabela2[[#This Row],[CURSOS]] -> ENF-INS (Multidisciplinar II)EMF-ISN | D20: =IF(Tabela2[[#This Row],[SITUAÇÃO]]<>"Demitido",CONCATENATE(Tabela2[[#This Row],[POLO]],Tabela2[[#This Row],[CURSOS]]),"Substituição") -> Baturité/CEEMF-ISN | E20: ENF-INS (Multidisciplinar II) | F20: EMF-ISN | G20: Baturité/CE | H20: Aline Camurca Mesquita | I20: =IFERROR(_xlfn.XLOOKUP(Tabela2[[#This Row],[CHAPA]],TUT.CONTROL!F:F,TUT.CONTROL!I:I),_xlfn.XLOOKUP(Tabela2[[#This Row],[CHAPA]],'REG.CONTROL'!F:F,'REG.CONTROL'!I:I)) -> Ativo | J20: =IFERROR(_xlfn.XLOOKUP(Tabela2[[#This Row],[NOME DO TUTOR]],TUT.CONTROL!C:C,TUT.CONTROL!G:G),"Atualizar") -> 46118 | K20: 85996297339 | L20: =IFERROR(_xlfn.XLOOKUP(Tabela2[[#This Row],[NOME DO TUTOR]],TUT.CONTROL!C:C,TUT.CONTROL!F:F),"Atualizar") -> 1158001198 | M20: aline.mesquita@tutorpratica.uniasselvi.com.br | N20: =IFERROR(_xlfn.XLOOKUP(Tabela2[[#This Row],[CHAPA]],TUT.CONTROL!F:F,TUT.CONTROL!H:H),_xlfn.XLOOKUP(Tabela2[[#This Row],[CHAPA]],'REG.CONTROL'!F:F,'REG.CONTROL'!H:H)) -> TUTOR DE PRATICA (UC_1749) | O20: =IFERROR(_xlfn.XLOOKUP(Tabela2[[#This Row],[NOME DO TUTOR]],TUT.CONTROL!C:C,TUT.CONTROL!K:K),"Atualizar") -> 004:00 | P20: =IF(Tabela2[[#This Row],[SITUAÇÃO]]="Demitido",IFERROR(_xlfn.XLOOKUP(Tabela2[[#This Row],[CHAPA]],TUT.CONTROL!F:F,TUT.CONTROL!V:V),_xlfn.XLOOKUP(Tabela2[[#This Row],[CHAPA]],'REG.CONTROL'!F:F,'REG.CONTROL'!V:V)),"-") -> -
A21: =IF(Tabela2[[#This Row],[SITUAÇÃO]]="Férias",CONCATENATE(Tabela2[[#This Row],[POLO]],Tabela2[[#This Row],[CURSOS]],Tabela2[[#This Row],[CATEGORIA]]),IF(Tabela2[[#This Row],[SITUAÇÃO]]="Ativo",CONCATENATE(Tabela2[[#This Row],[POLO]],Tabela2[[#This Row],[CURSOS]],Tabela2[[#This Row],[CATEGORIA]]),"desligado")) -> desligado | B21: =Tabela2[[#This Row],[CATEGORIA]]&Tabela2[[#This Row],[CURSOS]]&"LAP - "&Tabela2[[#This Row],[POLO]] -> ENF-INS (Multidisciplinar II)EMF-ISNLAP - Baturité/CE | C21: =Tabela2[[#This Row],[CATEGORIA]]&Tabela2[[#This Row],[CURSOS]] -> ENF-INS (Multidisciplinar II)EMF-ISN | D21: =IF(Tabela2[[#This Row],[SITUAÇÃO]]<>"Demitido",CONCATENATE(Tabela2[[#This Row],[POLO]],Tabela2[[#This Row],[CURSOS]]),"Substituição") -> Substituição | E21: ENF-INS (Multidisciplinar II) | F21: EMF-ISN | G21: Baturité/CE | H21: =PROPER("ALINE CAMURCA MESQUITA") -> Aline Camurca Mesquita | I21: =IFERROR(_xlfn.XLOOKUP(Tabela2[[#This Row],[CHAPA]],TUT.CONTROL!F:F,TUT.CONTROL!I:I),_xlfn.XLOOKUP(Tabela2[[#This Row],[CHAPA]],'REG.CONTROL'!F:F,'REG.CONTROL'!I:I)) -> Demitido | J21: =IFERROR(_xlfn.XLOOKUP(Tabela2[[#This Row],[NOME DO TUTOR]],'REG.CONTROL'!C:C,'REG.CONTROL'!G:G),"Demitido") -> 45048 | K21: 85996297339 | L21: =IFERROR(_xlfn.XLOOKUP(Tabela2[[#This Row],[NOME DO TUTOR]],'REG.CONTROL'!C:C,'REG.CONTROL'!F:F),"Demitido") -> 1004011951 | M21: aline.mesquita@regentedepolo.uniasselvi.com.br | N21: =IFERROR(_xlfn.XLOOKUP(Tabela2[[#This Row],[CHAPA]],TUT.CONTROL!F:F,TUT.CONTROL!H:H),_xlfn.XLOOKUP(Tabela2[[#This Row],[CHAPA]],'REG.CONTROL'!F:F,'REG.CONTROL'!H:H)) -> PROFESSOR REGENTE DE POLO (UC_1744) | O21: =IFERROR(_xlfn.XLOOKUP(Tabela2[[#This Row],[NOME DO TUTOR]],TUT.CONTROL!C:C,TUT.CONTROL!K:K),"Demitido") -> 004:00 | P21: =IF(Tabela2[[#This Row],[SITUAÇÃO]]="Demitido",IFERROR(_xlfn.XLOOKUP(Tabela2[[#This Row],[CHAPA]],TUT.CONTROL!F:F,TUT.CONTROL!V:V),_xlfn.XLOOKUP(Tabela2[[#This Row],[CHAPA]],'REG.CONTROL'!F:F,'REG.CONTROL'!V:V)),"-") -> 45841 | Q21: Desligado
A22: =IF(Tabela2[[#This Row],[SITUAÇÃO]]="Férias",CONCATENATE(Tabela2[[#This Row],[POLO]],Tabela2[[#This Row],[CURSOS]],Tabela2[[#This Row],[CATEGORIA]]),IF(Tabela2[[#This Row],[SITUAÇÃO]]="Ativo",CONCATENATE(Tabela2[[#This Row],[POLO]],Tabela2[[#This Row],[CURSOS]],Tabela2[[#This Row],[CATEGORIA]]),"desligado")) -> desligado | B22: =Tabela2[[#This Row],[CATEGORIA]]&Tabela2[[#This Row],[CURSOS]]&"LAP - "&Tabela2[[#This Row],[POLO]] -> ENF-INS (Multidisciplinar II)EMF-ISNLAP - Baturité/CE | C22: =Tabela2[[#This Row],[CATEGORIA]]&Tabela2[[#This Row],[CURSOS]] -> ENF-INS (Multidisciplinar II)EMF-ISN | D22: =IF(Tabela2[[#This Row],[SITUAÇÃO]]<>"Demitido",CONCATENATE(Tabela2[[#This Row],[POLO]],Tabela2[[#This Row],[CURSOS]]),"Substituição") -> Substituição | E22: ENF-INS (Multidisciplinar II) | F22: EMF-ISN | G22: Baturité/CE | H22: Raiane Martins Da Silva | I22: =IFERROR(_xlfn.XLOOKUP(Tabela2[[#This Row],[CHAPA]],TUT.CONTROL!F:F,TUT.CONTROL!I:I),_xlfn.XLOOKUP(Tabela2[[#This Row],[CHAPA]],'REG.CONTROL'!F:F,'REG.CONTROL'!I:I)) -> Demitido | J22: =IFERROR(_xlfn.XLOOKUP(Tabela2[[#This Row],[NOME DO TUTOR]],TUT.CONTROL!C:C,TUT.CONTROL!G:G),"Demitido") -> 45901 | K22: 85997962465 | L22: =IFERROR(_xlfn.XLOOKUP(Tabela2[[#This Row],[NOME DO TUTOR]],TUT.CONTROL!C:C,TUT.CONTROL!F:F),"Demitido") -> 1158000952 | M22: raiane.silva@tutorpratica.uniasselvi.com.br | N22: =IFERROR(_xlfn.XLOOKUP(Tabela2[[#This Row],[CHAPA]],TUT.CONTROL!F:F,TUT.CONTROL!H:H),_xlfn.XLOOKUP(Tabela2[[#This Row],[CHAPA]],'REG.CONTROL'!F:F,'REG.CONTROL'!H:H)) -> TUTOR DE PRATICA (UC_1749) | O22: =IFERROR(_xlfn.XLOOKUP(Tabela2[[#This Row],[NOME DO TUTOR]],TUT.CONTROL!C:C,TUT.CONTROL!K:K),"Demitido") -> 004:00 | P22: =IF(Tabela2[[#This Row],[SITUAÇÃO]]="Demitido",IFERROR(_xlfn.XLOOKUP(Tabela2[[#This Row],[CHAPA]],TUT.CONTROL!F:F,TUT.CONTROL!V:V),_xlfn.XLOOKUP(Tabela2[[#This Row],[CHAPA]],'REG.CONTROL'!F:F,'REG.CONTROL'!V:V)),"-") -> 45931 | Q22: Desligado
A23: =IF(Tabela2[[#This Row],[SITUAÇÃO]]="Férias",CONCATENATE(Tabela2[[#This Row],[POLO]],Tabela2[[#This Row],[CURSOS]],Tabela2[[#This Row],[CATEGORIA]]),IF(Tabela2[[#This Row],[SITUAÇÃO]]="Ativo",CONCATENATE(Tabela2[[#This Row],[POLO]],Tabela2[[#This Row],[CURSOS]],Tabela2[[#This Row],[CATEGORIA]]),"desligado")) -> Belém/PA - São BrásEMF-ISNENF-INS (Multidisciplinar II) | B23: =Tabela2[[#This Row],[CATEGORIA]]&Tabela2[[#This Row],[CURSOS]]&"LAP - "&Tabela2[[#This Row],[POLO]] -> ENF-INS (Multidisciplinar II)EMF-ISNLAP - Belém/PA - São Brás | C23: =Tabela2[[#This Row],[CATEGORIA]]&Tabela2[[#This Row],[CURSOS]] -> ENF-INS (Multidisciplinar II)EMF-ISN | D23: =IF(Tabela2[[#This Row],[SITUAÇÃO]]<>"Demitido",CONCATENATE(Tabela2[[#This Row],[POLO]],Tabela2[[#This Row],[CURSOS]]),"Substituição") -> Belém/PA - São BrásEMF-ISN | E23: ENF-INS (Multidisciplinar II) | F23: EMF-ISN | G23: Belém/PA - São Brás | H23: Edenilza Fabiana De Almeida Santos | I23: =IFERROR(_xlfn.XLOOKUP(Tabela2[[#This Row],[CHAPA]],TUT.CONTROL!F:F,TUT.CONTROL!I:I),_xlfn.XLOOKUP(Tabela2[[#This Row],[CHAPA]],'REG.CONTROL'!F:F,'REG.CONTROL'!I:I)) -> Ativo | J23: =IFERROR(_xlfn.XLOOKUP(Tabela2[[#This Row],[NOME DO TUTOR]],TUT.CONTROL!C:C,TUT.CONTROL!G:G),"Demitido") -> 45763 | K23: 91 9995-8831 | L23: =IFERROR(_xlfn.XLOOKUP(Tabela2[[#This Row],[NOME DO TUTOR]],TUT.CONTROL!C:C,TUT.CONTROL!F:F),"Demitido") -> 1158000707 | M23: edenilza.santos@tutorpratica.uniasselvi.com.br | N23: =IFERROR(_xlfn.XLOOKUP(Tabela2[[#This Row],[CHAPA]],TUT.CONTROL!F:F,TUT.CONTROL!H:H),_xlfn.XLOOKUP(Tabela2[[#This Row],[CHAPA]],'REG.CONTROL'!F:F,'REG.CONTROL'!H:H)) -> TUTOR DE PRATICA (UC_1749) | O23: =IFERROR(_xlfn.XLOOKUP(Tabela2[[#This Row],[NOME DO TUTOR]],TUT.CONTROL!C:C,TUT.CONTROL!K:K),"Demitido") -> 004:00 | P23: =IF(Tabela2[[#This Row],[SITUAÇÃO]]="Demitido",IFERROR(_xlfn.XLOOKUP(Tabela2[[#This Row],[CHAPA]],TUT.CONTROL!F:F,TUT.CONTROL!V:V),_xlfn.XLOOKUP(Tabela2[[#This Row],[CHAPA]],'REG.CONTROL'!F:F,'REG.CONTROL'!V:V)),"-") -> - | Q23: OK | R23: COREN-PA | S23: 52266
A24: =IF(Tabela2[[#This Row],[SITUAÇÃO]]="Férias",CONCATENATE(Tabela2[[#This Row],[POLO]],Tabela2[[#This Row],[CURSOS]],Tabela2[[#This Row],[CATEGORIA]]),IF(Tabela2[[#This Row],[SITUAÇÃO]]="Ativo",CONCATENATE(Tabela2[[#This Row],[POLO]],Tabela2[[#This Row],[CURSOS]],Tabela2[[#This Row],[CATEGORIA]]),"desligado")) -> Belo Horizonte/MG - BarreiroEMF-ISNENF-INS (Multidisciplinar II) | B24: =Tabela2[[#This Row],[CATEGORIA]]&Tabela2[[#This Row],[CURSOS]]&"LAP - "&Tabela2[[#This Row],[POLO]] -> ENF-INS (Multidisciplinar II)EMF-ISNLAP - Belo Horizonte/MG - Barreiro | C24: =Tabela2[[#This Row],[CATEGORIA]]&Tabela2[[#This Row],[CURSOS]] -> ENF-INS (Multidisciplinar II)EMF-ISN | D24: =IF(Tabela2[[#This Row],[SITUAÇÃO]]<>"Demitido",CONCATENATE(Tabela2[[#This Row],[POLO]],Tabela2[[#This Row],[CURSOS]]),"Substituição") -> Belo Horizonte/MG - BarreiroEMF-ISN | E24: ENF-INS (Multidisciplinar II) | F24: EMF-ISN | G24: Belo Horizonte/MG - Barreiro | H24: Italo Leonardo Fernandes Faria | I24: =IFERROR(_xlfn.XLOOKUP(Tabela2[[#This Row],[CHAPA]],TUT.CONTROL!F:F,TUT.CONTROL!I:I),_xlfn.XLOOKUP(Tabela2[[#This Row],[CHAPA]],'REG.CONTROL'!F:F,'REG.CONTROL'!I:I)) -> Ativo | J24: =IFERROR(_xlfn.XLOOKUP(Tabela2[[#This Row],[NOME DO TUTOR]],TUT.CONTROL!C:C,TUT.CONTROL!G:G),"Demitido") -> 45796 | K24: 31991693997 | L24: =IFERROR(_xlfn.XLOOKUP(Tabela2[[#This Row],[NOME DO TUTOR]],TUT.CONTROL!C:C,TUT.CONTROL!F:F),"Demitido") -> 1158000641 | M24: italo.faria@tutorpratica.uniasselvi.com.br | N24: =IFERROR(_xlfn.XLOOKUP(Tabela2[[#This Row],[CHAPA]],TUT.CONTROL!F:F,TUT.CONTROL!H:H),_xlfn.XLOOKUP(Tabela2[[#This Row],[CHAPA]],'REG.CONTROL'!F:F,'REG.CONTROL'!H:H)) -> TUTOR DE PRATICA (UC_1749) | O24: =IFERROR(_xlfn.XLOOKUP(Tabela2[[#This Row],[NOME DO TUTOR]],TUT.CONTROL!C:C,TUT.CONTROL!K:K),"Demitido") -> 004:00 | P24: =IF(Tabela2[[#This Row],[SITUAÇÃO]]="Demitido",IFERROR(_xlfn.XLOOKUP(Tabela2[[#This Row],[CHAPA]],TUT.CONTROL!F:F,TUT.CONTROL!V:V),_xlfn.XLOOKUP(Tabela2[[#This Row],[CHAPA]],'REG.CONTROL'!F:F,'REG.CONTROL'!V:V)),"-") -> - | Q24: OK | R24: COREN-MG | S24: 712824
A25: =IF(Tabela2[[#This Row],[SITUAÇÃO]]="Férias",CONCATENATE(Tabela2[[#This Row],[POLO]],Tabela2[[#This Row],[CURSOS]],Tabela2[[#This Row],[CATEGORIA]]),IF(Tabela2[[#This Row],[SITUAÇÃO]]="Ativo",CONCATENATE(Tabela2[[#This Row],[POLO]],Tabela2[[#This Row],[CURSOS]],Tabela2[[#This Row],[CATEGORIA]]),"desligado")) -> desligado | B25: =Tabela2[[#This Row],[CATEGORIA]]&Tabela2[[#This Row],[CURSOS]]&"LAP - "&Tabela2[[#This Row],[POLO]] -> ENF-INS (Multidisciplinar II)EMF-ISNLAP - Belo Horizonte/MG - Shopping Estação BH | C25: =Tabela2[[#This Row],[CATEGORIA]]&Tabela2[[#This Row],[CURSOS]] -> ENF-INS (Multidisciplinar II)EMF-ISN | D25: =IF(Tabela2[[#This Row],[SITUAÇÃO]]<>"Demitido",CONCATENATE(Tabela2[[#This Row],[POLO]],Tabela2[[#This Row],[CURSOS]]),"Substituição") -> Substituição | E25: ENF-INS (Multidisciplinar II) | F25: EMF-ISN | G25: Belo Horizonte/MG - Shopping Estação BH | H25: Gislene Pace De Souza Santos Nascimento | I25: =IFERROR(_xlfn.XLOOKUP(Tabela2[[#This Row],[CHAPA]],TUT.CONTROL!F:F,TUT.CONTROL!I:I),_xlfn.XLOOKUP(Tabela2[[#This Row],[CHAPA]],'REG.CONTROL'!F:F,'REG.CONTROL'!I:I)) -> Demitido | J25: =IFERROR(_xlfn.XLOOKUP(Tabela2[[#This Row],[NOME DO TUTOR]],'REG.CONTROL'!C:C,'REG.CONTROL'!G:G),"Demitido") -> 44840 | K25: 31987848509 | L25: =IFERROR(_xlfn.XLOOKUP(Tabela2[[#This Row],[NOME DO TUTOR]],'REG.CONTROL'!C:C,'REG.CONTROL'!F:F),"Demitido") -> 1004010883 | M25: gislene.nascimento@regentedepolo.uniasselvi.com.br | N25: =IFERROR(_xlfn.XLOOKUP(Tabela2[[#This Row],[CHAPA]],TUT.CONTROL!F:F,TUT.CONTROL!H:H),_xlfn.XLOOKUP(Tabela2[[#This Row],[CHAPA]],'REG.CONTROL'!F:F,'REG.CONTROL'!H:H)) -> PROFESSOR REGENTE DE POLO (UC_1744) | O25: =IFERROR(_xlfn.XLOOKUP(Tabela2[[#This Row],[NOME DO TUTOR]],'REGENTE CH'!A:A,'REGENTE CH'!C:C),"Atualizar") -> 004:00 | P25: =IF(Tabela2[[#This Row],[SITUAÇÃO]]="Demitido",IFERROR(_xlfn.XLOOKUP(Tabela2[[#This Row],[CHAPA]],TUT.CONTROL!F:F,TUT.CONTROL!V:V),_xlfn.XLOOKUP(Tabela2[[#This Row],[CHAPA]],'REG.CONTROL'!F:F,'REG.CONTROL'!V:V)),"-") -> 46083 | Q25: Desligado | R25: COREN-MG | S25: 293520
A26: =IF(Tabela2[[#This Row],[SITUAÇÃO]]="Férias",CONCATENATE(Tabela2[[#This Row],[POLO]],Tabela2[[#This Row],[CURSOS]],Tabela2[[#This Row],[CATEGORIA]]),IF(Tabela2[[#This Row],[SITUAÇÃO]]="Ativo",CONCATENATE(Tabela2[[#This Row],[POLO]],Tabela2[[#This Row],[CURSOS]],Tabela2[[#This Row],[CATEGORIA]]),"desligado")) -> desligado | B26: =Tabela2[[#This Row],[CATEGORIA]]&Tabela2[[#This Row],[CURSOS]]&"LAP - "&Tabela2[[#This Row],[POLO]] -> ENF-INS (Multidisciplinar II)EMF-ISNLAP - Belo Horizonte/MG - Shopping Estação BH | C26: =Tabela2[[#This Row],[CATEGORIA]]&Tabela2[[#This Row],[CURSOS]] -> ENF-INS (Multidisciplinar II)EMF-ISN | D26: =IF(Tabela2[[#This Row],[SITUAÇÃO]]<>"Demitido",CONCATENATE(Tabela2[[#This Row],[POLO]],Tabela2[[#This Row],[CURSOS]]),"Substituição") -> Substituição | E26: ENF-INS (Multidisciplinar II) | F26: EMF-ISN | G26: Belo Horizonte/MG - Shopping Estação BH | H26: Yasmin Tatielle De Sousa Santos | I26: =IFERROR(_xlfn.XLOOKUP(Tabela2[[#This Row],[CHAPA]],TUT.CONTROL!F:F,TUT.CONTROL!I:I),_xlfn.XLOOKUP(Tabela2[[#This Row],[CHAPA]],'REG.CONTROL'!F:F,'REG.CONTROL'!I:I)) -> Demitido | J26: =IFERROR(_xlfn.XLOOKUP(Tabela2[[#This Row],[NOME DO TUTOR]],TUT.CONTROL!C:C,TUT.CONTROL!G:G),"Demitido") -> 45908 | K26: 31983580817 | L26: =IFERROR(_xlfn.XLOOKUP(Tabela2[[#This Row],[NOME DO TUTOR]],TUT.CONTROL!C:C,TUT.CONTROL!F:F),"Demitido") -> 1158000962 | M26: yasmin.santos@tutorpratica.uniasselvi.com.br | N26: =IFERROR(_xlfn.XLOOKUP(Tabela2[[#This Row],[CHAPA]],TUT.CONTROL!F:F,TUT.CONTROL!H:H),_xlfn.XLOOKUP(Tabela2[[#This Row],[CHAPA]],'REG.CONTROL'!F:F,'REG.CONTROL'!H:H)) -> TUTOR DE PRATICA (UC_1749) | O26: =IFERROR(_xlfn.XLOOKUP(Tabela2[[#This Row],[NOME DO TUTOR]],TUT.CONTROL!C:C,TUT.CONTROL!K:K),"Demitido") -> 004:00 | P26: =IF(Tabela2[[#This Row],[SITUAÇÃO]]="Demitido",IFERROR(_xlfn.XLOOKUP(Tabela2[[#This Row],[CHAPA]],TUT.CONTROL!F:F,TUT.CONTROL!V:V),_xlfn.XLOOKUP(Tabela2[[#This Row],[CHAPA]],'REG.CONTROL'!F:F,'REG.CONTROL'!V:V)),"-") -> 45940 | Q26: Desligado | R26: COREN-MG | S26: 698.026
A27: =IF(Tabela2[[#This Row],[SITUAÇÃO]]="Férias",CONCATENATE(Tabela2[[#This Row],[POLO]],Tabela2[[#This Row],[CURSOS]],Tabela2[[#This Row],[CATEGORIA]]),IF(Tabela2[[#This Row],[SITUAÇÃO]]="Ativo",CONCATENATE(Tabela2[[#This Row],[POLO]],Tabela2[[#This Row],[CURSOS]],Tabela2[[#This Row],[CATEGORIA]]),"desligado")) -> desligado | B27: =Tabela2[[#This Row],[CATEGORIA]]&Tabela2[[#This Row],[CURSOS]]&"LAP - "&Tabela2[[#This Row],[POLO]] -> ENF-INS (Multidisciplinar II)EMF-ISNLAP - Bento Gonçalves/RS | C27: =Tabela2[[#This Row],[CATEGORIA]]&Tabela2[[#This Row],[CURSOS]] -> ENF-INS (Multidisciplinar II)EMF-ISN | D27: =IF(Tabela2[[#This Row],[SITUAÇÃO]]<>"Demitido",CONCATENATE(Tabela2[[#This Row],[POLO]],Tabela2[[#This Row],[CURSOS]]),"Substituição") -> Substituição | E27: ENF-INS (Multidisciplinar II) | F27: EMF-ISN | G27: Bento Gonçalves/RS | H27: Juliana Brito Ferreira | I27: =IFERROR(_xlfn.XLOOKUP(Tabela2[[#This Row],[CHAPA]],TUT.CONTROL!F:F,TUT.CONTROL!I:I),_xlfn.XLOOKUP(Tabela2[[#This Row],[CHAPA]],'REG.CONTROL'!F:F,'REG.CONTROL'!I:I)) -> Demitido | J27: =IFERROR(_xlfn.XLOOKUP(Tabela2[[#This Row],[NOME DO TUTOR]],TUT.CONTROL!C:C,TUT.CONTROL!G:G),"Demitido") -> 45735 | K27: 53981047737 | L27: =IFERROR(_xlfn.XLOOKUP(Tabela2[[#This Row],[NOME DO TUTOR]],TUT.CONTROL!C:C,TUT.CONTROL!F:F),"Demitido") -> 1158000572 | M27: juliana.ferreira@tutorpratica.uniasselvi.com.br | N27: =IFERROR(_xlfn.XLOOKUP(Tabela2[[#This Row],[CHAPA]],TUT.CONTROL!F:F,TUT.CONTROL!H:H),_xlfn.XLOOKUP(Tabela2[[#This Row],[CHAPA]],'REG.CONTROL'!F:F,'REG.CONTROL'!H:H)) -> TUTOR DE PRATICA (UC_1749) | O27: =IFERROR(_xlfn.XLOOKUP(Tabela2[[#This Row],[NOME DO TUTOR]],TUT.CONTROL!C:C,TUT.CONTROL!K:K),"Demitido") -> 004:00 | P27: =IF(Tabela2[[#This Row],[SITUAÇÃO]]="Demitido",IFERROR(_xlfn.XLOOKUP(Tabela2[[#This Row],[CHAPA]],TUT.CONTROL!F:F,TUT.CONTROL!V:V),_xlfn.XLOOKUP(Tabela2[[#This Row],[CHAPA]],'REG.CONTROL'!F:F,'REG.CONTROL'!V:V)),"-") -> 46072 | Q27: Desligado | R27: COREN-RS | S27: 655325
A28: =IF(Tabela2[[#This Row],[SITUAÇÃO]]="Férias",CONCATENATE(Tabela2[[#This Row],[POLO]],Tabela2[[#This Row],[CURSOS]],Tabela2[[#This Row],[CATEGORIA]]),IF(Tabela2[[#This Row],[SITUAÇÃO]]="Ativo",CONCATENATE(Tabela2[[#This Row],[POLO]],Tabela2[[#This Row],[CURSOS]],Tabela2[[#This Row],[CATEGORIA]]),"desligado")) -> desligado | B28: =Tabela2[[#This Row],[CATEGORIA]]&Tabela2[[#This Row],[CURSOS]]&"LAP - "&Tabela2[[#This Row],[POLO]] -> ENF-INS (Multidisciplinar II)EMF-ISNLAP - Blumenau/SC - Salto Do Norte (Centro Universitário Dante) | C28: =Tabela2[[#This Row],[CATEGORIA]]&Tabela2[[#This Row],[CURSOS]] -> ENF-INS (Multidisciplinar II)EMF-ISN | D28: =IF(Tabela2[[#This Row],[SITUAÇÃO]]<>"Demitido",CONCATENATE(Tabela2[[#This Row],[POLO]],Tabela2[[#This Row],[CURSOS]]),"Substituição") -> Substituição | E28: ENF-INS (Multidisciplinar II) | F28: EMF-ISN | G28: Blumenau/SC - Salto Do Norte (Centro Universitário Dante) | H28: Matheus Pereira De Oliveira | I28: =IFERROR(_xlfn.XLOOKUP(Tabela2[[#This Row],[CHAPA]],TUT.CONTROL!F:F,TUT.CONTROL!I:I),_xlfn.XLOOKUP(Tabela2[[#This Row],[CHAPA]],'REG.CONTROL'!F:F,'REG.CONTROL'!I:I)) -> Demitido | J28: =IFERROR(_xlfn.XLOOKUP(Tabela2[[#This Row],[NOME DO TUTOR]],TUT.CONTROL!C:C,TUT.CONTROL!G:G),"Demitido") -> 45754 | K28: 47 9289-1794 | L28: =IFERROR(_xlfn.XLOOKUP(Tabela2[[#This Row],[NOME DO TUTOR]],TUT.CONTROL!C:C,TUT.CONTROL!F:F),"Demitido") -> 1158000709 | M28: matheus.oliveira@tutorpratica.uniasselvi.com.br | N28: =IFERROR(_xlfn.XLOOKUP(Tabela2[[#This Row],[CHAPA]],TUT.CONTROL!F:F,TUT.CONTROL!H:H),_xlfn.XLOOKUP(Tabela2[[#This Row],[CHAPA]],'REG.CONTROL'!F:F,'REG.CONTROL'!H:H)) -> TUTOR DE PRATICA (UC_1749) | O28: =IFERROR(_xlfn.XLOOKUP(Tabela2[[#This Row],[NOME DO TUTOR]],TUT.CONTROL!C:C,TUT.CONTROL!K:K),"Demitido") -> 004:00 | P28: =IF(Tabela2[[#This Row],[SITUAÇÃO]]="Demitido",IFERROR(_xlfn.XLOOKUP(Tabela2[[#This Row],[CHAPA]],TUT.CONTROL!F:F,TUT.CONTROL!V:V),_xlfn.XLOOKUP(Tabela2[[#This Row],[CHAPA]],'REG.CONTROL'!F:F,'REG.CONTROL'!V:V)),"-") -> 45888 | Q28: Desligado
A29: =IF(Tabela2[[#This Row],[SITUAÇÃO]]="Férias",CONCATENATE(Tabela2[[#This Row],[POLO]],Tabela2[[#This Row],[CURSOS]],Tabela2[[#This Row],[CATEGORIA]]),IF(Tabela2[[#This Row],[SITUAÇÃO]]="Ativo",CONCATENATE(Tabela2[[#This Row],[POLO]],Tabela2[[#This Row],[CURSOS]],Tabela2[[#This Row],[CATEGORIA]]),"desligado")) -> Boa Viagem/CEEMF-ISNENF-INS (Multidisciplinar II) | B29: =Tabela2[[#This Row],[CATEGORIA]]&Tabela2[[#This Row],[CURSOS]]&"LAP - "&Tabela2[[#This Row],[POLO]] -> ENF-INS (Multidisciplinar II)EMF-ISNLAP - Boa Viagem/CE | C29: =Tabela2[[#This Row],[CATEGORIA]]&Tabela2[[#This Row],[CURSOS]] -> ENF-INS (Multidisciplinar II)EMF-ISN | D29: =IF(Tabela2[[#This Row],[SITUAÇÃO]]<>"Demitido",CONCATENATE(Tabela2[[#This Row],[POLO]],Tabela2[[#This Row],[CURSOS]]),"Substituição") -> Boa Viagem/CEEMF-ISN | E29: ENF-INS (Multidisciplinar II) | F29: EMF-ISN | G29: Boa Viagem/CE | H29: Aparecida Heliane Cavalcante Oliveira | I29: =IFERROR(_xlfn.XLOOKUP(Tabela2[[#This Row],[CHAPA]],TUT.CONTROL!F:F,TUT.CONTROL!I:I),_xlfn.XLOOKUP(Tabela2[[#This Row],[CHAPA]],'REG.CONTROL'!F:F,'REG.CONTROL'!I:I)) -> Ativo | J29: =IFERROR(_xlfn.XLOOKUP(Tabela2[[#This Row],[NOME DO TUTOR]],TUT.CONTROL!C:C,TUT.CONTROL!G:G),"Atualizar") -> 46118 | K29: 88988029822 | L29: =IFERROR(_xlfn.XLOOKUP(Tabela2[[#This Row],[NOME DO TUTOR]],TUT.CONTROL!C:C,TUT.CONTROL!F:F),"Atualizar") -> 1158001197 | M29: aparecida.oliveira@tutorpratica.uniasselvi.com.br | N29: =IFERROR(_xlfn.XLOOKUP(Tabela2[[#This Row],[CHAPA]],TUT.CONTROL!F:F,TUT.CONTROL!H:H),_xlfn.XLOOKUP(Tabela2[[#This Row],[CHAPA]],'REG.CONTROL'!F:F,'REG.CONTROL'!H:H)) -> TUTOR DE PRATICA (UC_1749) | O29: =IFERROR(_xlfn.XLOOKUP(Tabela2[[#This Row],[NOME DO TUTOR]],TUT.CONTROL!C:C,TUT.CONTROL!K:K),"Atualizar") -> 004:00 | P29: =IF(Tabela2[[#This Row],[SITUAÇÃO]]="Demitido",IFERROR(_xlfn.XLOOKUP(Tabela2[[#This Row],[CHAPA]],TUT.CONTROL!F:F,TUT.CONTROL!V:V),_xlfn.XLOOKUP(Tabela2[[#This Row],[CHAPA]],'REG.CONTROL'!F:F,'REG.CONTROL'!V:V)),"-") -> -
A30: =IF(Tabela2[[#This Row],[SITUAÇÃO]]="Férias",CONCATENATE(Tabela2[[#This Row],[POLO]],Tabela2[[#This Row],[CURSOS]],Tabela2[[#This Row],[CATEGORIA]]),IF(Tabela2[[#This Row],[SITUAÇÃO]]="Ativo",CONCATENATE(Tabela2[[#This Row],[POLO]],Tabela2[[#This Row],[CURSOS]],Tabela2[[#This Row],[CATEGORIA]]),"desligado")) -> desligado | B30: =Tabela2[[#This Row],[CATEGORIA]]&Tabela2[[#This Row],[CURSOS]]&"LAP - "&Tabela2[[#This Row],[POLO]] -> ENF-INS (Multidisciplinar II)EMF-ISNLAP - Boa Viagem/CE | C30: =Tabela2[[#This Row],[CATEGORIA]]&Tabela2[[#This Row],[CURSOS]] -> ENF-INS (Multidisciplinar II)EMF-ISN | D30: =IF(Tabela2[[#This Row],[SITUAÇÃO]]<>"Demitido",CONCATENATE(Tabela2[[#This Row],[POLO]],Tabela2[[#This Row],[CURSOS]]),"Substituição") -> Substituição | E30: ENF-INS (Multidisciplinar II) | F30: EMF-ISN | G30: Boa Viagem/CE | H30: Jayne Cavalcante Torres | I30: =IFERROR(_xlfn.XLOOKUP(Tabela2[[#This Row],[CHAPA]],TUT.CONTROL!F:F,TUT.CONTROL!I:I),_xlfn.XLOOKUP(Tabela2[[#This Row],[CHAPA]],'REG.CONTROL'!F:F,'REG.CONTROL'!I:I)) -> Demitido | J30: =IFERROR(_xlfn.XLOOKUP(Tabela2[[#This Row],[NOME DO TUTOR]],TUT.CONTROL!C:C,TUT.CONTROL!G:G),"Demitido") -> 45735 | K30: 85992009088 | L30: =IFERROR(_xlfn.XLOOKUP(Tabela2[[#This Row],[NOME DO TUTOR]],TUT.CONTROL!C:C,TUT.CONTROL!F:F),"Demitido") -> 1158000576 | M30: jayne.torres@tutorpratica.uniasselvi.com.br | N30: =IFERROR(_xlfn.XLOOKUP(Tabela2[[#This Row],[CHAPA]],TUT.CONTROL!F:F,TUT.CONTROL!H:H),_xlfn.XLOOKUP(Tabela2[[#This Row],[CHAPA]],'REG.CONTROL'!F:F,'REG.CONTROL'!H:H)) -> TUTOR DE PRATICA (UC_1749) | O30: =IFERROR(_xlfn.XLOOKUP(Tabela2[[#This Row],[NOME DO TUTOR]],TUT.CONTROL!C:C,TUT.CONTROL!K:K),"Demitido") -> 004:00 | P30: =IF(Tabela2[[#This Row],[SITUAÇÃO]]="Demitido",IFERROR(_xlfn.XLOOKUP(Tabela2[[#This Row],[CHAPA]],TUT.CONTROL!F:F,TUT.CONTROL!V:V),_xlfn.XLOOKUP(Tabela2[[#This Row],[CHAPA]],'REG.CONTROL'!F:F,'REG.CONTROL'!V:V)),"-") -> 45919 | Q30: Desligado | R30: COREN-CE | S30: 589632
A31: =IF(Tabela2[[#This Row],[SITUAÇÃO]]="Férias",CONCATENATE(Tabela2[[#This Row],[POLO]],Tabela2[[#This Row],[CURSOS]],Tabela2[[#This Row],[CATEGORIA]]),IF(Tabela2[[#This Row],[SITUAÇÃO]]="Ativo",CONCATENATE(Tabela2[[#This Row],[POLO]],Tabela2[[#This Row],[CURSOS]],Tabela2[[#This Row],[CATEGORIA]]),"desligado")) -> Boa Vista/RR - CentroEMF-ISNENF-INS (Multidisciplinar II) | B31: =Tabela2[[#This Row],[CATEGORIA]]&Tabela2[[#This Row],[CURSOS]]&"LAP - "&Tabela2[[#This Row],[POLO]] -> ENF-INS (Multidisciplinar II)EMF-ISNLAP - Boa Vista/RR - Centro | C31: =Tabela2[[#This Row],[CATEGORIA]]&Tabela2[[#This Row],[CURSOS]] -> ENF-INS (Multidisciplinar II)EMF-ISN | D31: =IF(Tabela2[[#This Row],[SITUAÇÃO]]<>"Demitido",CONCATENATE(Tabela2[[#This Row],[POLO]],Tabela2[[#This Row],[CURSOS]]),"Substituição") -> Boa Vista/RR - CentroEMF-ISN | E31: ENF-INS (Multidisciplinar II) | F31: EMF-ISN | G31: Boa Vista/RR - Centro | H31: Cleiton Mendes Honorato Sousa | I31: =IFERROR(_xlfn.XLOOKUP(Tabela2[[#This Row],[CHAPA]],TUT.CONTROL!F:F,TUT.CONTROL!I:I),_xlfn.XLOOKUP(Tabela2[[#This Row],[CHAPA]],'REG.CONTROL'!F:F,'REG.CONTROL'!I:I)) -> Ativo | J31: =IFERROR(_xlfn.XLOOKUP(Tabela2[[#This Row],[NOME DO TUTOR]],TUT.CONTROL!C:C,TUT.CONTROL!G:G),"Atualizar") -> 46118 | K31: 95991389750 | L31: =IFERROR(_xlfn.XLOOKUP(Tabela2[[#This Row],[NOME DO TUTOR]],TUT.CONTROL!C:C,TUT.CONTROL!F:F),"Atualizar") -> 1158001184 | M31: cleiton.sousa@tutorpratica.uniasselvi.com.br | N31: =IFERROR(_xlfn.XLOOKUP(Tabela2[[#This Row],[CHAPA]],TUT.CONTROL!F:F,TUT.CONTROL!H:H),_xlfn.XLOOKUP(Tabela2[[#This Row],[CHAPA]],'REG.CONTROL'!F:F,'REG.CONTROL'!H:H)) -> TUTOR DE PRATICA (UC_1749) | O31: =IFERROR(_xlfn.XLOOKUP(Tabela2[[#This Row],[NOME DO TUTOR]],TUT.CONTROL!C:C,TUT.CONTROL!K:K),"Atualizar") -> 004:00 | P31: =IF(Tabela2[[#This Row],[SITUAÇÃO]]="Demitido",IFERROR(_xlfn.XLOOKUP(Tabela2[[#This Row],[CHAPA]],TUT.CONTROL!F:F,TUT.CONTROL!V:V),_xlfn.XLOOKUP(Tabela2[[#This Row],[CHAPA]],'REG.CONTROL'!F:F,'REG.CONTROL'!V:V)),"-") -> - | S31: 113839
