Workbook

Sheet Sheet1
A1: Id | B1: Hora de início | C1: Hora de conclusão | D1: Email | E1: Nome | F1: Total de pontos | G1: Comentários do teste | H1: Hora de postagem da nota | I1: Selecione seu Polo Laboratório de Atividades Presenciais: | J1: Pontos – Selecione seu Polo Laboratório de Atividades Presenciais: | K1: Comentários – Selecione seu Polo Laboratório de Atividades Presenciais: | L1: Selecione a Ordem de Disciplina | M1: Pontos – Selecione a Ordem de Disciplina | N1: Comentários – Selecione a Ordem de Disciplina | O1: Selecione a Categoria do Laboratório desta atividade prática: | P1: Pontos – Selecione a Categoria do Laboratório desta atividade prática: | Q1: Comentários – Selecione a Categoria do Laboratório desta atividade prática: | R1: Selecione quais Protocolos de Atividades Práticas foram realizados no laboratório: | S1: Pontos – Selecione quais Protocolos de Atividades Práticas foram realizados no laboratório: | T1: Comentários – Selecione quais Protocolos de Atividades Práticas foram realizados no laboratório: | U1: Data da aplicação do Protocolo de Prática: | V1: Pontos – Data da aplicação do Protocolo de Prática: | W1: Comentários – Data da aplicação do Protocolo de Prática: | X1: Quantos Estudantes presentes neste Experimento? | Y1: Pontos – Quantos Estudantes presentes neste Experimento? | Z1: Comentários – Quantos Estudantes presentes neste Experimento? | AA1: Envio da Lista de Presença: | AB1: Pontos – Envio da Lista de Presença: | AC1: Comentários – Envio da Lista de Presença: | AD1: Envio do Portfólio em PDF: | AE1: Pontos – Envio do Portfólio em PDF: | AF1: Comentários – Envio do Portfólio em PDF: | AG1: Selecione quais Protocolos de Atividades Práticas foram realizados no laboratório:1 | AH1: Pontos – Selecione quais Protocolos de Atividades Práticas foram realizados no laboratório:1 | AI1: Comentários – Selecione quais Protocolos de Atividades Práticas foram realizados no laboratório:1 | AJ1: Data da aplicação do Protocolo de Prática:1 | AK1: Pontos – Data da aplicação do Protocolo de Prática:1 | AL1: Comentários – Data da aplicação do Protocolo de Prática:1 | AM1: Quantos Estudantes presentes neste Experimento?1 | AN1: Pontos – Quantos Estudantes presentes neste Experimento?1 | AO1: Comentários – Quantos Estudantes presentes neste Experimento?1 | AP1: Envio da Lista de Presença:1 | AQ1: Pontos – Envio da Lista de Presença:1 | AR1: Comentários – Envio da Lista de Presença:1 | AS1: Envio do Portfólio em PDF:1 | AT1: Pontos – Envio do Portfólio em PDF:1 | AU1: Comentários – Envio do Portfólio em PDF:1 | AV1: Selecione quais Protocolos de Atividades Práticas foram realizados no laboratório:2 | AW1: Pontos – Selecione quais Protocolos de Atividades Práticas foram realizados no laboratório:2 | AX1: Comentários – Selecione quais Protocolos de Atividades Práticas foram realizados no laboratório:2 | AY1: Data da aplicação do Protocolo de Prática:2 | AZ1: Pontos – Data da aplicação do Protocolo de Prática:2 | BA1: Comentários – Data da aplicação do Protocolo de Prática:2 | BB1: Quantos Estudantes presentes neste Experimento?2 | BC1: Pontos – Quantos Estudantes presentes neste Experimento?2 | BD1: Comentários – Quantos Estudantes presentes neste Experimento?2 | BE1: Envio da Lista de Presença:2 | BF1: Pontos – Envio da Lista de Presença:2 | BG1: Comentários – Envio da Lista de Presença:2 | BH1: Envio do Portfólio em PDF:2 | BI1: Pontos – Envio do Portfólio em PDF:2 | BJ1: Comentários – Envio do Portfólio em PDF:2 | BK1: Selecione quais Protocolos de Atividades Práticas foram realizados no laboratório:3 | BL1: Pontos – Selecione quais Protocolos de Atividades Práticas foram realizados no laboratório:3 | BM1: Comentários – Selecione quais Protocolos de Atividades Práticas foram realizados no laboratório:3 | BN1: Data da aplicação do Protocolo de Prática:3 | BO1: Pontos – Data da aplicação do Protocolo de Prática:3 | BP1: Comentários – Data da aplicação do Protocolo de Prática:3 | BQ1: Quantos Estudantes presentes neste Experimento?3 | BR1: Pontos – Quantos Estudantes presentes neste Experimento?3 | BS1: Comentários – Quantos Estudantes presentes neste Experimento?3 | BT1: Envio da Lista de Presença:3 | BU1: Pontos – Envio da Lista de Presença:3 | BV1: Comentários – Envio da Lista de Presença:3 | BW1: Envio do Portfólio em PDF:3 | BX1: Pontos – Envio do Portfólio em PDF:3 | BY1: Comentários – Envio do Portfólio em PDF:3 | BZ1: Selecione quais Protocolos de Atividades Práticas foram realizados no laboratório:4 | CA1: Pontos – Selecione quais Protocolos de Atividades Práticas foram realizados no laboratório:4 | CB1: Comentários – Selecione quais Protocolos de Atividades Práticas foram realizados no laboratório:4 | CC1: Data da aplicação do Protocolo de Prática:4 | CD1: Pontos – Data da aplicação do Protocolo de Prática:4 | CE1: Comentários – Data da aplicação do Protocolo de Prática:4 | CF1: Quantos Estudantes presentes neste Experimento?4 | CG1: Pontos – Quantos Estudantes presentes neste Experimento?4 | CH1: Comentários – Quantos Estudantes presentes neste Experimento?4 | CI1: Envio da Lista de Presença:4 | CJ1: Pontos – Envio da Lista de Presença:4 | CK1: Comentários – Envio da Lista de Presença:4 | CL1: Envio do Portfólio em PDF:4 | CM1: Pontos – Envio do Portfólio em PDF:4 | CN1: Comentários – Envio do Portfólio em PDF:4 | CO1: Selecione quais Protocolos de Atividades Práticas foram realizados no laboratório:5 | CP1: Pontos – Selecione quais Protocolos de Atividades Práticas foram realizados no laboratório:5 | CQ1: Comentários – Selecione quais Protocolos de Atividades Práticas foram realizados no laboratório:5 | CR1: Data da aplicação do Protocolo de Prática:5 | CS1: Pontos – Data da aplicação do Protocolo de Prática:5 | CT1: Comentários – Data da aplicação do Protocolo de Prática:5 | CU1: Quantos Estudantes presentes neste Experimento?5 | CV1: Pontos – Quantos Estudantes presentes neste Experimento?5 | CW1: Comentários – Quantos Estudantes presentes neste Experimento?5 | CX1: Envio da Lista de Presença:5 | CY1: Pontos – Envio da Lista de Presença:5 | CZ1: Comentários – Envio da Lista de Presença:5 | DA1: Envio do Portfólio em PDF:5 | DB1: Pontos – Envio do Portfólio em PDF:5 | DC1: Comentários – Envio do Portfólio em PDF:5 | DD1: Selecione quais Protocolos de Atividades Práticas foram realizados no laboratório:6 | DE1: Pontos – Selecione quais Protocolos de Atividades Práticas foram realizados no laboratório:6 | DF1: Comentários – Selecione quais Protocolos de Atividades Práticas foram realizados no laboratório:6 | DG1: Data da aplicação do Protocolo de Prática:6 | DH1: Pontos – Data da aplicação do Protocolo de Prática:6 | DI1: Comentários – Data da aplicação do Protocolo de Prática:6 | DJ1: Quantos Estudantes presentes neste Experimento?6 | DK1: Pontos – Quantos Estudantes presentes neste Experimento?6 | DL1: Comentários – Quantos Estudantes presentes neste Experimento?6 | DM1: Envio da Lista de Presença:6 | DN1: Pontos – Envio da Lista de Presença:6 | DO1: Comentários – Envio da Lista de Presença:6 | DP1: Envio do Portfólio em PDF:6 | DQ1: Pontos – Envio do Portfólio em PDF:6 | DR1: Comentários – Envio do Portfólio em PDF:6 | DS1: CHAVE CONVERSÃO | DT1: CHAVE LINK POLO | DU1: Selecione quais Protocolos de Atividades Práticas foram realizados no laboratório:7 | DV1: Data da aplicação do Protocolo de Prática:7 | DW1: Quantos Estudantes presentes neste Experimento?72 | DX1: Nome do tutor | DY1: Ordem da prática
A2: 2 | B2: 46072.613 | C2: 46072.613 | D2: lucas.medeiros@tutorpratica.uniasselvi.com.br | E2: Lucas Medeiros | I2: Guarujá/SP | L2: Ordem 1 | O2: Multidisciplinar III - Biomedicina Estética, Fisioterapia, Terapia Ocupacional e Estética e Cosmética | AV2: Massagem Geral Terapêutica: Técnicas e Aplicações em Recursos Manuais | AY2: 46071 | BB2: 1 | BE2: https://uniasselvi01-my.sharepoint.com/personal/elienai_cesar_uniasselvi_com_br1/Documents/Aplicativos/Microsoft%20Forms/Question%C3%A1rio%20sem%20t%C3%ADtulo/Envio%20da%20Lista%20de%20Presen%C3%A7a%201/IMG_0809_Lucas%20Medeiros.PNG | BH2: https://uniasselvi01-my.sharepoint.com/personal/elienai_cesar_uniasselvi_com_br1/Documents/Aplicativos/Microsoft%20Forms/Question%C3%A1rio%20sem%20t%C3%ADtulo/Envio%20do%20Portf%C3%B3lio%20em%20PDF%201/massagem%201_Lucas%20Medeiros.pdf | DS2: =_xlfn.XLOOKUP(OfficeForms.Table[[#This Row],[Selecione a Categoria do Laboratório desta atividade prática:]],Planilha1!A:A,Planilha1!B:B) -> BFI | DT2: =CONCATENATE(OfficeForms.Table[[#This Row],[Selecione seu Polo Laboratório de Atividades Presenciais:]],OfficeForms.Table[[#This Row],[CHAVE CONVERSÃO]]) -> Guarujá/SPBFI | DU2: =CONCATENATE(OfficeForms.Table[[#This Row],[Selecione quais Protocolos de Atividades Práticas foram realizados no laboratório:]],OfficeForms.Table[[#This Row],[Selecione quais Protocolos de Atividades Práticas foram realizados no laboratório:1]],OfficeForms.Table[[#This Row],[Selecione quais Protocolos de Atividades Práticas foram realizados no laboratório:2]],OfficeForms.Table[[#This Row],[Selecione quais Protocolos de Atividades Práticas foram realizados no laboratório:3]],OfficeForms.Table[[#This Row],[Selecione quais Protocolos de Atividades Práticas foram realizados no laboratório:4]],OfficeForms.Table[[#This Row],[Selecione quais Protocolos de Atividades Práticas foram realizados no laboratório:5]],OfficeForms.Table[[#This Row],[Selecione quais Protocolos de Atividades Práticas foram realizados no laboratório:6]]) -> Massagem Geral Terapêutica: Técnicas e Aplicações em Recursos Manuais | DV2: =SUM(OfficeForms.Table[[#This Row],[Data da aplicação do Protocolo de Prática:]],OfficeForms.Table[[#This Row],[Data da aplicação do Protocolo de Prática:1]],OfficeForms.Table[[#This Row],[Data da aplicação do Protocolo de Prática:2]],OfficeForms.Table[[#This Row],[Data da aplicação do Protocolo de Prática:3]],OfficeForms.Table[[#This Row],[Data da aplicação do Protocolo de Prática:4]],OfficeForms.Table[[#This Row],[Data da aplicação do Protocolo de Prática:5]],OfficeForms.Table[[#This Row],[Data da aplicação do Protocolo de Prática:6]]) -> 46071 | DW2: =SUM(OfficeForms.Table[[#This Row],[Quantos Estudantes presentes neste Experimento?]],OfficeForms.Table[[#This Row],[Quantos Estudantes presentes neste Experimento?1]],OfficeForms.Table[[#This Row],[Quantos Estudantes presentes neste Experimento?2]],OfficeForms.Table[[#This Row],[Quantos Estudantes presentes neste Experimento?3]],OfficeForms.Table[[#This Row],[Quantos Estudantes presentes neste Experimento?4]],OfficeForms.Table[[#This Row],[Quantos Estudantes presentes neste Experimento?5]],OfficeForms.Table[[#This Row],[Quantos Estudantes presentes neste Experimento?6]]) -> 1 | DX2: =_xlfn.XLOOKUP(OfficeForms.Table[[#This Row],[CHAVE LINK POLO]],'[1]Quadro Geral de Lotação'!$B:$B,'[1]Quadro Geral de Lotação'!$I:$I) -> Lucas Soares De Medeiros | DY2: =OfficeForms.Table[[#This Row],[Selecione a Ordem de Disciplina]] -> Ordem 1
A3: 3 | B3: 46072.823 | C3: 46072.825 | D3: gabriela.santos@tutorpratica.uniasselvi.com.br | E3: Gabriela Santos | I3: Chapecó/SC - Centro | L3: Ordem 1 | O3: EngeMaker | Química e Física - Engenharias e Licenciaturas | BZ3: ENGMAKER - Medição da resistência elétrica | CC3: 46072 | CF3: 0 | CI3: https://uniasselvi01-my.sharepoint.com/personal/elienai_cesar_uniasselvi_com_br1/Documents/Aplicativos/Microsoft%20Forms/Question%C3%A1rio%20sem%20t%C3%ADtulo/Envio%20da%20Lista%20de%20Presen%C3%A7a%203/MODELO_Lista%20de%20Presen%C3%A7a%20das%20Pr%C3%A1ticas_Gabriela%20Santos.pdf | CL3: https://uniasselvi01-my.sharepoint.com/personal/elienai_cesar_uniasselvi_com_br1/Documents/Aplicativos/Microsoft%20Forms/Question%C3%A1rio%20sem%20t%C3%ADtulo/Envio%20do%20Portf%C3%B3lio%20em%20PDF%203/Portf%C3%B3lio%20pratica%20Medindo%20valores%20de%20resist%C3%AAn_Gabriela%20Santos.pdf | DS3: =_xlfn.XLOOKUP(OfficeForms.Table[[#This Row],[Selecione a Categoria do Laboratório desta atividade prática:]],Planilha1!A:A,Planilha1!B:B) -> ECE-ENM-ENS-ENG-EEA-GPI-CDE-OBR-SAN-TER-FSA-SLF-QUI | DT3: =CONCATENATE(OfficeForms.Table[[#This Row],[Selecione seu Polo Laboratório de Atividades Presenciais:]],OfficeForms.Table[[#This Row],[CHAVE CONVERSÃO]]) -> Chapecó/SC - CentroECE-ENM-ENS-ENG-EEA-GPI-CDE-OBR-SAN-TER-FSA-SLF-QUI | DU3: =CONCATENATE(OfficeForms.Table[[#This Row],[Selecione quais Protocolos de Atividades Práticas foram realizados no laboratório:]],OfficeForms.Table[[#This Row],[Selecione quais Protocolos de Atividades Práticas foram realizados no laboratório:1]],OfficeForms.Table[[#This Row],[Selecione quais Protocolos de Atividades Práticas foram realizados no laboratório:2]],OfficeForms.Table[[#This Row],[Selecione quais Protocolos de Atividades Práticas foram realizados no laboratório:3]],OfficeForms.Table[[#This Row],[Selecione quais Protocolos de Atividades Práticas foram realizados no laboratório:4]],OfficeForms.Table[[#This Row],[Selecione quais Protocolos de Atividades Práticas foram realizados no laboratório:5]],OfficeForms.Table[[#This Row],[Selecione quais Protocolos de Atividades Práticas foram realizados no laboratório:6]]) -> ENGMAKER - Medição da resistência elétrica | DV3: =SUM(OfficeForms.Table[[#This Row],[Data da aplicação do Protocolo de Prática:]],OfficeForms.Table[[#This Row],[Data da aplicação do Protocolo de Prática:1]],OfficeForms.Table[[#This Row],[Data da aplicação do Protocolo de Prática:2]],OfficeForms.Table[[#This Row],[Data da aplicação do Protocolo de Prática:3]],OfficeForms.Table[[#This Row],[Data da aplicação do Protocolo de Prática:4]],OfficeForms.Table[[#This Row],[Data da aplicação do Protocolo de Prática:5]],OfficeForms.Table[[#This Row],[Data da aplicação do Protocolo de Prática:6]]) -> 46072 | DW3: =SUM(OfficeForms.Table[[#This Row],[Quantos Estudantes presentes neste Experimento?]],OfficeForms.Table[[#This Row],[Quantos Estudantes presentes neste Experimento?1]],OfficeForms.Table[[#This Row],[Quantos Estudantes presentes neste Experimento?2]],OfficeForms.Table[[#This Row],[Quantos Estudantes presentes neste Experimento?3]],OfficeForms.Table[[#This Row],[Quantos Estudantes presentes neste Experimento?4]],OfficeForms.Table[[#This Row],[Quantos Estudantes presentes neste Experimento?5]],OfficeForms.Table[[#This Row],[Quantos Estudantes presentes neste Experimento?6]]) -> 0 | DX3: =_xlfn.XLOOKUP(OfficeForms.Table[[#This Row],[CHAVE LINK POLO]],'[1]Quadro Geral de Lotação'!$B:$B,'[1]Quadro Geral de Lotação'!$I:$I) -> Gabriela Fanck Dos Santos | DY3: =OfficeForms.Table[[#This Row],[Selecione a Ordem de Disciplina]] -> Ordem 1
A4: 4 | B4: 46072.825 | C4: 46072.827 | D4: gabriela.santos@tutorpratica.uniasselvi.com.br | E4: Gabriela Santos | I4: Chapecó/SC - Centro | L4: Ordem 1 | O4: EngeMaker | Química e Física - Engenharias e Licenciaturas | BZ4: QUÍMICA E FÍSICA - Associação De Resistores Em Série e Paralelo | CC4: 46072 | CF4: 0 | CI4: https://uniasselvi01-my.sharepoint.com/personal/elienai_cesar_uniasselvi_com_br1/Documents/Aplicativos/Microsoft%20Forms/Question%C3%A1rio%20sem%20t%C3%ADtulo/Envio%20da%20Lista%20de%20Presen%C3%A7a%203/MODELO_Lista%20de%20Presen%C3%A7a%20das%20Pr%C3%A1ticas_Gabriela%20Santos%201.pdf | CL4: https://uniasselvi01-my.sharepoint.com/personal/elienai_cesar_uniasselvi_com_br1/Documents/Aplicativos/Microsoft%20Forms/Question%C3%A1rio%20sem%20t%C3%ADtulo/Envio%20do%20Portf%C3%B3lio%20em%20PDF%203/Associa%C3%A7%C3%A3o%20De%20Resistores%20Em%20S%C3%A9rie%20e%20Paralelo_Gabriela%20Santos.pdf | DS4: =_xlfn.XLOOKUP(OfficeForms.Table[[#This Row],[Selecione a Categoria do Laboratório desta atividade prática:]],Planilha1!A:A,Planilha1!B:B) -> ECE-ENM-ENS-ENG-EEA-GPI-CDE-OBR-SAN-TER-FSA-SLF-QUI | DT4: =CONCATENATE(OfficeForms.Table[[#This Row],[Selecione seu Polo Laboratório de Atividades Presenciais:]],OfficeForms.Table[[#This Row],[CHAVE CONVERSÃO]]) -> Chapecó/SC - CentroECE-ENM-ENS-ENG-EEA-GPI-CDE-OBR-SAN-TER-FSA-SLF-QUI | DU4: =CONCATENATE(OfficeForms.Table[[#This Row],[Selecione quais Protocolos de Atividades Práticas foram realizados no laboratório:]],OfficeForms.Table[[#This Row],[Selecione quais Protocolos de Atividades Práticas foram realizados no laboratório:1]],OfficeForms.Table[[#This Row],[Selecione quais Protocolos de Atividades Práticas foram realizados no laboratório:2]],OfficeForms.Table[[#This Row],[Selecione quais Protocolos de Atividades Práticas foram realizados no laboratório:3]],OfficeForms.Table[[#This Row],[Selecione quais Protocolos de Atividades Práticas foram realizados no laboratório:4]],OfficeForms.Table[[#This Row],[Selecione quais Protocolos de Atividades Práticas foram realizados no laboratório:5]],OfficeForms.Table[[#This Row],[Selecione quais Protocolos de Atividades Práticas foram realizados no laboratório:6]]) -> QUÍMICA E FÍSICA - Associação De Resistores Em Série e Paralelo | DV4: =SUM(OfficeForms.Table[[#This Row],[Data da aplicação do Protocolo de Prática:]],OfficeForms.Table[[#This Row],[Data da aplicação do Protocolo de Prática:1]],OfficeForms.Table[[#This Row],[Data da aplicação do Protocolo de Prática:2]],OfficeForms.Table[[#This Row],[Data da aplicação do Protocolo de Prática:3]],OfficeForms.Table[[#This Row],[Data da aplicação do Protocolo de Prática:4]],OfficeForms.Table[[#This Row],[Data da aplicação do Protocolo de Prática:5]],OfficeForms.Table[[#This Row],[Data da aplicação do Protocolo de Prática:6]]) -> 46072 | DW4: =SUM(OfficeForms.Table[[#This Row],[Quantos Estudantes presentes neste Experimento?]],OfficeForms.Table[[#This Row],[Quantos Estudantes presentes neste Experimento?1]],OfficeForms.Table[[#This Row],[Quantos Estudantes presentes neste Experimento?2]],OfficeForms.Table[[#This Row],[Quantos Estudantes presentes neste Experimento?3]],OfficeForms.Table[[#This Row],[Quantos Estudantes presentes neste Experimento?4]],OfficeForms.Table[[#This Row],[Quantos Estudantes presentes neste Experimento?5]],OfficeForms.Table[[#This Row],[Quantos Estudantes presentes neste Experimento?6]]) -> 0 | DX4: =_xlfn.XLOOKUP(OfficeForms.Table[[#This Row],[CHAVE LINK POLO]],'[1]Quadro Geral de Lotação'!$B:$B,'[1]Quadro Geral de Lotação'!$I:$I) -> Gabriela Fanck Dos Santos | DY4: =OfficeForms.Table[[#This Row],[Selecione a Ordem de Disciplina]] -> Ordem 1
A5: 5 | B5: 46073.423 | C5: 46073.425 | D5: paulo.silva@tutorpratica.uniasselvi.com.br | E5: Paulo Silva | I5: Itajaí/SC - São Vicente | L5: Ordem 1 | O5: Multidisciplinar III - Biomedicina Estética, Fisioterapia, Terapia Ocupacional e Estética e Cosmética | AV5: Pontos cardeais | AY5: 46072 | BB5: 5 | BE5: https://uniasselvi01-my.sharepoint.com/personal/elienai_cesar_uniasselvi_com_br1/Documents/Aplicativos/Microsoft%20Forms/Question%C3%A1rio%20sem%20t%C3%ADtulo/Envio%20da%20Lista%20de%20Presen%C3%A7a%201/CamScanner%2020-02-2026%2010.06_Paulo%20Silva.pdf | BH5: https://uniasselvi01-my.sharepoint.com/personal/elienai_cesar_uniasselvi_com_br1/Documents/Aplicativos/Microsoft%20Forms/Question%C3%A1rio%20sem%20t%C3%ADtulo/Envio%20do%20Portf%C3%B3lio%20em%20PDF%201/Tutor%20-%20Portf%C3%B3lio%20das%20Atividades%20Pr%C3%A1ticas-mes_Paulo%20Silva.pdf | DS5: =_xlfn.XLOOKUP(OfficeForms.Table[[#This Row],[Selecione a Categoria do Laboratório desta atividade prática:]],Planilha1!A:A,Planilha1!B:B) -> BFI | DT5: =CONCATENATE(OfficeForms.Table[[#This Row],[Selecione seu Polo Laboratório de Atividades Presenciais:]],OfficeForms.Table[[#This Row],[CHAVE CONVERSÃO]]) -> Itajaí/SC - São VicenteBFI | DU5: =CONCATENATE(OfficeForms.Table[[#This Row],[Selecione quais Protocolos de Atividades Práticas foram realizados no laboratório:]],OfficeForms.Table[[#This Row],[Selecione quais Protocolos de Atividades Práticas foram realizados no laboratório:1]],OfficeForms.Table[[#This Row],[Selecione quais Protocolos de Atividades Práticas foram realizados no laboratório:2]],OfficeForms.Table[[#This Row],[Selecione quais Protocolos de Atividades Práticas foram realizados no laboratório:3]],OfficeForms.Table[[#This Row],[Selecione quais Protocolos de Atividades Práticas foram realizados no laboratório:4]],OfficeForms.Table[[#This Row],[Selecione quais Protocolos de Atividades Práticas foram realizados no laboratório:5]],OfficeForms.Table[[#This Row],[Selecione quais Protocolos de Atividades Práticas foram realizados no laboratório:6]]) -> Pontos cardeais | DV5: =SUM(OfficeForms.Table[[#This Row],[Data da aplicação do Protocolo de Prática:]],OfficeForms.Table[[#This Row],[Data da aplicação do Protocolo de Prática:1]],OfficeForms.Table[[#This Row],[Data da aplicação do Protocolo de Prática:2]],OfficeForms.Table[[#This Row],[Data da aplicação do Protocolo de Prática:3]],OfficeForms.Table[[#This Row],[Data da aplicação do Protocolo de Prática:4]],OfficeForms.Table[[#This Row],[Data da aplicação do Protocolo de Prática:5]],OfficeForms.Table[[#This Row],[Data da aplicação do Protocolo de Prática:6]]) -> 46072 | DW5: =SUM(OfficeForms.Table[[#This Row],[Quantos Estudantes presentes neste Experimento?]],OfficeForms.Table[[#This Row],[Quantos Estudantes presentes neste Experimento?1]],OfficeForms.Table[[#This Row],[Quantos Estudantes presentes neste Experimento?2]],OfficeForms.Table[[#This Row],[Quantos Estudantes presentes neste Experimento?3]],OfficeForms.Table[[#This Row],[Quantos Estudantes presentes neste Experimento?4]],OfficeForms.Table[[#This Row],[Quantos Estudantes presentes neste Experimento?5]],OfficeForms.Table[[#This Row],[Quantos Estudantes presentes neste Experimento?6]]) -> 5 | DX5: =_xlfn.XLOOKUP(OfficeForms.Table[[#This Row],[CHAVE LINK POLO]],'[1]Quadro Geral de Lotação'!$B:$B,'[1]Quadro Geral de Lotação'!$I:$I) -> Tuani Rafaela Matana Neves | DY5: =OfficeForms.Table[[#This Row],[Selecione a Ordem de Disciplina]] -> Ordem 1
A6: 6 | B6: 46073.475 | C6: 46073.477 | D6: juliana.berger@tutorpratica.uniasselvi.com.br | E6: Juliana Berger | I6: Novo Hamburgo/RS - Centro | L6: Ordem 1 | O6: Multidisciplinar IV - Nutrição | BK6: Avaliação nutricional de gestante I: Antropometria | BN6: 46071 | BQ6: 14 | BT6: https://uniasselvi01-my.sharepoint.com/personal/elienai_cesar_uniasselvi_com_br1/Documents/Aplicativos/Microsoft%20Forms/Question%C3%A1rio%20sem%20t%C3%ADtulo/Envio%20da%20Lista%20de%20Presen%C3%A7a%202/WhatsApp%20Image%202026-02-20%20at%2011.06.32_Juliana%20Berger.jpeg; https://uniasselvi01-my.sharepoint.com/personal/elienai_cesar_uniasselvi_com_br1/Documents/Aplicativos/Microsoft%20Forms/Question%C3%A1rio%20sem%20t%C3%ADtulo/Envio%20da%20Lista%20de%20Presen%C3%A7a%202/WhatsApp%20Image%202026-02-20%20at%2011.06.31_Juliana%20Berger.jpeg | BW6: https://uniasselvi01-my.sharepoint.com/personal/elienai_cesar_uniasselvi_com_br1/Documents/Aplicativos/Microsoft%20Forms/Question%C3%A1rio%20sem%20t%C3%ADtulo/Envio%20do%20Portf%C3%B3lio%20em%20PDF%202/Portf%C3%B3lio%20das%20Atividades%20Pr%C3%A1ticas_avalia%C3%A7%C3%A3o%20n_Juliana%20Berger.pdf | DS6: =_xlfn.XLOOKUP(OfficeForms.Table[[#This Row],[Selecione a Categoria do Laboratório desta atividade prática:]],Planilha1!A:A,Planilha1!B:B) -> NTR | DT6: =CONCATENATE(OfficeForms.Table[[#This Row],[Selecione seu Polo Laboratório de Atividades Presenciais:]],OfficeForms.Table[[#This Row],[CHAVE CONVERSÃO]]) -> Novo Hamburgo/RS - CentroNTR | DU6: =CONCATENATE(OfficeForms.Table[[#This Row],[Selecione quais Protocolos de Atividades Práticas foram realizados no laboratório:]],OfficeForms.Table[[#This Row],[Selecione quais Protocolos de Atividades Práticas foram realizados no laboratório:1]],OfficeForms.Table[[#This Row],[Selecione quais Protocolos de Atividades Práticas foram realizados no laboratório:2]],OfficeForms.Table[[#This Row],[Selecione quais Protocolos de Atividades Práticas foram realizados no laboratório:3]],OfficeForms.Table[[#This Row],[Selecione quais Protocolos de Atividades Práticas foram realizados no laboratório:4]],OfficeForms.Table[[#This Row],[Selecione quais Protocolos de Atividades Práticas foram realizados no laboratório:5]],OfficeForms.Table[[#This Row],[Selecione quais Protocolos de Atividades Práticas foram realizados no laboratório:6]]) -> Avaliação nutricional de gestante I: Antropometria | DV6: =SUM(OfficeForms.Table[[#This Row],[Data da aplicação do Protocolo de Prática:]],OfficeForms.Table[[#This Row],[Data da aplicação do Protocolo de Prática:1]],OfficeForms.Table[[#This Row],[Data da aplicação do Protocolo de Prática:2]],OfficeForms.Table[[#This Row],[Data da aplicação do Protocolo de Prática:3]],OfficeForms.Table[[#This Row],[Data da aplicação do Protocolo de Prática:4]],OfficeForms.Table[[#This Row],[Data da aplicação do Protocolo de Prática:5]],OfficeForms.Table[[#This Row],[Data da aplicação do Protocolo de Prática:6]]) -> 46071 | DW6: =SUM(OfficeForms.Table[[#This Row],[Quantos Estudantes presentes neste Experimento?]],OfficeForms.Table[[#This Row],[Quantos Estudantes presentes neste Experimento?1]],OfficeForms.Table[[#This Row],[Quantos Estudantes presentes neste Experimento?2]],OfficeForms.Table[[#This Row],[Quantos Estudantes presentes neste Experimento?3]],OfficeForms.Table[[#This Row],[Quantos Estudantes presentes neste Experimento?4]],OfficeForms.Table[[#This Row],[Quantos Estudantes presentes neste Experimento?5]],OfficeForms.Table[[#This Row],[Quantos Estudantes presentes neste Experimento?6]]) -> 14 | DX6: =_xlfn.XLOOKUP(OfficeForms.Table[[#This Row],[CHAVE LINK POLO]],'[1]Quadro Geral de Lotação'!$B:$B,'[1]Quadro Geral de Lotação'!$I:$I) -> Juliana Berger | DY6: =OfficeForms.Table[[#This Row],[Selecione a Ordem de Disciplina]] -> Ordem 1
A7: 7 | B7: 46073.489 | C7: 46073.492 | D7: laura.volpato@tutorpratica.uniasselvi.com.br | E7: Laura Volpato | I7: Florianópolis/SC - Centro | L7: Ordem 1 | O7: Multidisciplinar IV - Nutrição | BK7: Avaliação nutricional de gestante I: Antropometria | BN7: 46072 | BQ7: 8 | BT7: https://uniasselvi01-my.sharepoint.com/personal/elienai_cesar_uniasselvi_com_br1/Documents/Aplicativos/Microsoft%20Forms/Question%C3%A1rio%20sem%20t%C3%ADtulo/Envio%20da%20Lista%20de%20Presen%C3%A7a%202/IMG_20260219_193949_Laura%20Volpato.jpg | BW7: https://uniasselvi01-my.sharepoint.com/personal/elienai_cesar_uniasselvi_com_br1/Documents/Aplicativos/Microsoft%20Forms/Question%C3%A1rio%20sem%20t%C3%ADtulo/Envio%20do%20Portf%C3%B3lio%20em%20PDF%202/1%20Portf%C3%B3lio%20das%20Atividades%20Pr%C3%A1ticas.docx%20(1)_Laura%20Volpato.pdf | DS7: =_xlfn.XLOOKUP(OfficeForms.Table[[#This Row],[Selecione a Categoria do Laboratório desta atividade prática:]],Planilha1!A:A,Planilha1!B:B) -> NTR | DT7: =CONCATENATE(OfficeForms.Table[[#This Row],[Selecione seu Polo Laboratório de Atividades Presenciais:]],OfficeForms.Table[[#This Row],[CHAVE CONVERSÃO]]) -> Florianópolis/SC - CentroNTR | DU7: =CONCATENATE(OfficeForms.Table[[#This Row],[Selecione quais Protocolos de Atividades Práticas foram realizados no laboratório:]],OfficeForms.Table[[#This Row],[Selecione quais Protocolos de Atividades Práticas foram realizados no laboratório:1]],OfficeForms.Table[[#This Row],[Selecione quais Protocolos de Atividades Práticas foram realizados no laboratório:2]],OfficeForms.Table[[#This Row],[Selecione quais Protocolos de Atividades Práticas foram realizados no laboratório:3]],OfficeForms.Table[[#This Row],[Selecione quais Protocolos de Atividades Práticas foram realizados no laboratório:4]],OfficeForms.Table[[#This Row],[Selecione quais Protocolos de Atividades Práticas foram realizados no laboratório:5]],OfficeForms.Table[[#This Row],[Selecione quais Protocolos de Atividades Práticas foram realizados no laboratório:6]]) -> Avaliação nutricional de gestante I: Antropometria | DV7: =SUM(OfficeForms.Table[[#This Row],[Data da aplicação do Protocolo de Prática:]],OfficeForms.Table[[#This Row],[Data da aplicação do Protocolo de Prática:1]],OfficeForms.Table[[#This Row],[Data da aplicação do Protocolo de Prática:2]],OfficeForms.Table[[#This Row],[Data da aplicação do Protocolo de Prática:3]],OfficeForms.Table[[#This Row],[Data da aplicação do Protocolo de Prática:4]],OfficeForms.Table[[#This Row],[Data da aplicação do Protocolo de Prática:5]],OfficeForms.Table[[#This Row],[Data da aplicação do Protocolo de Prática:6]]) -> 46072 | DW7: =SUM(OfficeForms.Table[[#This Row],[Quantos Estudantes presentes neste Experimento?]],OfficeForms.Table[[#This Row],[Quantos Estudantes presentes neste Experimento?1]],OfficeForms.Table[[#This Row],[Quantos Estudantes presentes neste Experimento?2]],OfficeForms.Table[[#This Row],[Quantos Estudantes presentes neste Experimento?3]],OfficeForms.Table[[#This Row],[Quantos Estudantes presentes neste Experimento?4]],OfficeForms.Table[[#This Row],[Quantos Estudantes presentes neste Experimento?5]],OfficeForms.Table[[#This Row],[Quantos Estudantes presentes neste Experimento?6]]) -> 8 | DX7: =_xlfn.XLOOKUP(OfficeForms.Table[[#This Row],[CHAVE LINK POLO]],'[1]Quadro Geral de Lotação'!$B:$B,'[1]Quadro Geral de Lotação'!$I:$I) -> Laura Volpato | DY7: =OfficeForms.Table[[#This Row],[Selecione a Ordem de Disciplina]] -> Ordem 1
A8: 8 | B8: 46073.492 | C8: 46073.494 | D8: laura.volpato@tutorpratica.uniasselvi.com.br | E8: Laura Volpato | I8: Florianópolis/SC - Centro | L8: Ordem 1 | O8: Multidisciplinar IV - Nutrição | BK8: Avaliação nutricional de gestante II: Anamnese e diagnóstico | BN8: 46072 | BQ8: 7 | BT8: https://uniasselvi01-my.sharepoint.com/personal/elienai_cesar_uniasselvi_com_br1/Documents/Aplicativos/Microsoft%20Forms/Question%C3%A1rio%20sem%20t%C3%ADtulo/Envio%20da%20Lista%20de%20Presen%C3%A7a%202/IMG_20260219_203429_Laura%20Volpato.jpg | BW8: https://uniasselvi01-my.sharepoint.com/personal/elienai_cesar_uniasselvi_com_br1/Documents/Aplicativos/Microsoft%20Forms/Question%C3%A1rio%20sem%20t%C3%ADtulo/Envio%20do%20Portf%C3%B3lio%20em%20PDF%202/2%20Portf%C3%B3lio%20das%20Atividades%20Pr%C3%A1ticas.docx_Laura%20Volpato.pdf | DS8: =_xlfn.XLOOKUP(OfficeForms.Table[[#This Row],[Selecione a Categoria do Laboratório desta atividade prática:]],Planilha1!A:A,Planilha1!B:B) -> NTR | DT8: =CONCATENATE(OfficeForms.Table[[#This Row],[Selecione seu Polo Laboratório de Atividades Presenciais:]],OfficeForms.Table[[#This Row],[CHAVE CONVERSÃO]]) -> Florianópolis/SC - CentroNTR | DU8: =CONCATENATE(OfficeForms.Table[[#This Row],[Selecione quais Protocolos de Atividades Práticas foram realizados no laboratório:]],OfficeForms.Table[[#This Row],[Selecione quais Protocolos de Atividades Práticas foram realizados no laboratório:1]],OfficeForms.Table[[#This Row],[Selecione quais Protocolos de Atividades Práticas foram realizados no laboratório:2]],OfficeForms.Table[[#This Row],[Selecione quais Protocolos de Atividades Práticas foram realizados no laboratório:3]],OfficeForms.Table[[#This Row],[Selecione quais Protocolos de Atividades Práticas foram realizados no laboratório:4]],OfficeForms.Table[[#This Row],[Selecione quais Protocolos de Atividades Práticas foram realizados no laboratório:5]],OfficeForms.Table[[#This Row],[Selecione quais Protocolos de Atividades Práticas foram realizados no laboratório:6]]) -> Avaliação nutricional de gestante II: Anamnese e diagnóstico | DV8: =SUM(OfficeForms.Table[[#This Row],[Data da aplicação do Protocolo de Prática:]],OfficeForms.Table[[#This Row],[Data da aplicação do Protocolo de Prática:1]],OfficeForms.Table[[#This Row],[Data da aplicação do Protocolo de Prática:2]],OfficeForms.Table[[#This Row],[Data da aplicação do Protocolo de Prática:3]],OfficeForms.Table[[#This Row],[Data da aplicação do Protocolo de Prática:4]],OfficeForms.Table[[#This Row],[Data da aplicação do Protocolo de Prática:5]],OfficeForms.Table[[#This Row],[Data da aplicação do Protocolo de Prática:6]]) -> 46072 | DW8: =SUM(OfficeForms.Table[[#This Row],[Quantos Estudantes presentes neste Experimento?]],OfficeForms.Table[[#This Row],[Quantos Estudantes presentes neste Experimento?1]],OfficeForms.Table[[#This Row],[Quantos Estudantes presentes neste Experimento?2]],OfficeForms.Table[[#This Row],[Quantos Estudantes presentes neste Experimento?3]],OfficeForms.Table[[#This Row],[Quantos Estudantes presentes neste Experimento?4]],OfficeForms.Table[[#This Row],[Quantos Estudantes presentes neste Experimento?5]],OfficeForms.Table[[#This Row],[Quantos Estudantes presentes neste Experimento?6]]) -> 7 | DX8: =_xlfn.XLOOKUP(OfficeForms.Table[[#This Row],[CHAVE LINK POLO]],'[1]Quadro Geral de Lotação'!$B:$B,'[1]Quadro Geral de Lotação'!$I:$I) -> Laura Volpato | DY8: =OfficeForms.Table[[#This Row],[Selecione a Ordem de Disciplina]] -> Ordem 1
A9: 9 | B9: 46073.579 | C9: 46073.597 | D9: vanessa.varjao@tutorpratica.uniasselvi.com.br | E9: Vanessa Varjao | I9: Paulo Afonso/BA - Tancredo Neves II | L9: Ordem 1 | O9: Multidisciplinar III - Biomedicina Estética, Fisioterapia, Terapia Ocupacional e Estética e Cosmética | AV9: Prática Terapêutica com Órteses: Abordagens Funcionais na Reabilitação Musculoesquelética;Fisioterapia com Próteses: Reabilitação Funcional e Adaptação ao Uso de Próteses | AY9: 46072 | BB9: 6 | BE9: https://uniasselvi01-my.sharepoint.com/personal/elienai_cesar_uniasselvi_com_br1/_layouts/15/Doc.aspx?sourcedoc=%7BBCA3181A-6644-47B4-8DFE-8DCE796C7622%7D&file=Lista%20de%20presen%C3%A7a%20Fevereiro_Vanessa%20Varjao.docx&action=default&mobileredirect=true | BH9: https://uniasselvi01-my.sharepoint.com/personal/elienai_cesar_uniasselvi_com_br1/_layouts/15/Doc.aspx?sourcedoc=%7BCC3E2066-442C-4F51-8FC1-FC5805E7E738%7D&file=Portf%C3%B3lio%20Fevereiro_Vanessa%20Varjao.docx&action=default&mobileredirect=true | DS9: =_xlfn.XLOOKUP(OfficeForms.Table[[#This Row],[Selecione a Categoria do Laboratório desta atividade prática:]],Planilha1!A:A,Planilha1!B:B) -> BFI | DT9: =CONCATENATE(OfficeForms.Table[[#This Row],[Selecione seu Polo Laboratório de Atividades Presenciais:]],OfficeForms.Table[[#This Row],[CHAVE CONVERSÃO]]) -> Paulo Afonso/BA - Tancredo Neves IIBFI | DU9: =CONCATENATE(OfficeForms.Table[[#This Row],[Selecione quais Protocolos de Atividades Práticas foram realizados no laboratório:]],OfficeForms.Table[[#This Row],[Selecione quais Protocolos de Atividades Práticas foram realizados no laboratório:1]],OfficeForms.Table[[#This Row],[Selecione quais Protocolos de Atividades Práticas foram realizados no laboratório:2]],OfficeForms.Table[[#This Row],[Selecione quais Protocolos de Atividades Práticas foram realizados no laboratório:3]],OfficeForms.Table[[#This Row],[Selecione quais Protocolos de Atividades Práticas foram realizados no laboratório:4]],OfficeForms.Table[[#This Row],[Selecione quais Protocolos de Atividades Práticas foram realizados no laboratório:5]],OfficeForms.Table[[#This Row],[Selecione quais Protocolos de Atividades Práticas foram realizados no laboratório:6]]) -> Prática Terapêutica com Órteses: Abordagens Funcionais na Reabilitação Musculoesquelética;Fisioterapia com Próteses: Reabilitação Funcional e Adaptação ao Uso de Próteses | DV9: =SUM(OfficeForms.Table[[#This Row],[Data da aplicação do Protocolo de Prática:]],OfficeForms.Table[[#This Row],[Data da aplicação do Protocolo de Prática:1]],OfficeForms.Table[[#This Row],[Data da aplicação do Protocolo de Prática:2]],OfficeForms.Table[[#This Row],[Data da aplicação do Protocolo de Prática:3]],OfficeForms.Table[[#This Row],[Data da aplicação do Protocolo de Prática:4]],OfficeForms.Table[[#This Row],[Data da aplicação do Protocolo de Prática:5]],OfficeForms.Table[[#This Row],[Data da aplicação do Protocolo de Prática:6]]) -> 46072 | DW9: =SUM(OfficeForms.Table[[#This Row],[Quantos Estudantes presentes neste Experimento?]],OfficeForms.Table[[#This Row],[Quantos Estudantes presentes neste Experimento?1]],OfficeForms.Table[[#This Row],[Quantos Estudantes presentes neste Experimento?2]],OfficeForms.Table[[#This Row],[Quantos Estudantes presentes neste Experimento?3]],OfficeForms.Table[[#This Row],[Quantos Estudantes presentes neste Experimento?4]],OfficeForms.Table[[#This Row],[Quantos Estudantes presentes neste Experimento?5]],OfficeForms.Table[[#This Row],[Quantos Estudantes presentes neste Experimento?6]]) -> 6 | DX9: =_xlfn.XLOOKUP(OfficeForms.Table[[#This Row],[CHAVE LINK POLO]],'[1]Quadro Geral de Lotação'!$B:$B,'[1]Quadro Geral de Lotação'!$I:$I) -> Vanessa Das Neves Varjao | DY9: =OfficeForms.Table[[#This Row],[Selecione a Ordem de Disciplina]] -> Ordem 1
A10: 10 | B10: 46073.668 | C10: 46073.68 | D10: marla.souza@tutorpratica.uniasselvi.com.br | E10: Marla Souza | I10: Catalão/GO | L10: Ordem 1 | O10: Química e Física - Agronomia | DD10: Técnicas de propagação de plantas | DG10: 46072 | DJ10: 20 | DM10: https://uniasselvi01-my.sharepoint.com/personal/elienai_cesar_uniasselvi_com_br1/Documents/Aplicativos/Microsoft%20Forms/Question%C3%A1rio%20sem%20t%C3%ADtulo/Envio%20da%20Lista%20de%20Presen%C3%A7a%205/Lista%20de%20Presen%C3%A7a_Marla%20Souza.pdf | DP10: https://uniasselvi01-my.sharepoint.com/personal/elienai_cesar_uniasselvi_com_br1/Documents/Aplicativos/Microsoft%20Forms/Question%C3%A1rio%20sem%20t%C3%ADtulo/Envio%20do%20Portf%C3%B3lio%20em%20PDF%205/Aula%20Pratica%20-%20Entomologia%20Agricola_Marla%20Souza.pdf | DS10: =_xlfn.XLOOKUP(OfficeForms.Table[[#This Row],[Selecione a Categoria do Laboratório desta atividade prática:]],Planilha1!A:A,Planilha1!B:B) -> AGM | DT10: =CONCATENATE(OfficeForms.Table[[#This Row],[Selecione seu Polo Laboratório de Atividades Presenciais:]],OfficeForms.Table[[#This Row],[CHAVE CONVERSÃO]]) -> Catalão/GOAGM | DU10: =CONCATENATE(OfficeForms.Table[[#This Row],[Selecione quais Protocolos de Atividades Práticas foram realizados no laboratório:]],OfficeForms.Table[[#This Row],[Selecione quais Protocolos de Atividades Práticas foram realizados no laboratório:1]],OfficeForms.Table[[#This Row],[Selecione quais Protocolos de Atividades Práticas foram realizados no laboratório:2]],OfficeForms.Table[[#This Row],[Selecione quais Protocolos de Atividades Práticas foram realizados no laboratório:3]],OfficeForms.Table[[#This Row],[Selecione quais Protocolos de Atividades Práticas foram realizados no laboratório:4]],OfficeForms.Table[[#This Row],[Selecione quais Protocolos de Atividades Práticas foram realizados no laboratório:5]],OfficeForms.Table[[#This Row],[Selecione quais Protocolos de Atividades Práticas foram realizados no laboratório:6]]) -> Técnicas de propagação de plantas | DV10: =SUM(OfficeForms.Table[[#This Row],[Data da aplicação do Protocolo de Prática:]],OfficeForms.Table[[#This Row],[Data da aplicação do Protocolo de Prática:1]],OfficeForms.Table[[#This Row],[Data da aplicação do Protocolo de Prática:2]],OfficeForms.Table[[#This Row],[Data da aplicação do Protocolo de Prática:3]],OfficeForms.Table[[#This Row],[Data da aplicação do Protocolo de Prática:4]],OfficeForms.Table[[#This Row],[Data da aplicação do Protocolo de Prática:5]],OfficeForms.Table[[#This Row],[Data da aplicação do Protocolo de Prática:6]]) -> 46072 | DW10: =SUM(OfficeForms.Table[[#This Row],[Quantos Estudantes presentes neste Experimento?]],OfficeForms.Table[[#This Row],[Quantos Estudantes presentes neste Experimento?1]],OfficeForms.Table[[#This Row],[Quantos Estudantes presentes neste Experimento?2]],OfficeForms.Table[[#This Row],[Quantos Estudantes presentes neste Experimento?3]],OfficeForms.Table[[#This Row],[Quantos Estudantes presentes neste Experimento?4]],OfficeForms.Table[[#This Row],[Quantos Estudantes presentes neste Experimento?5]],OfficeForms.Table[[#This Row],[Quantos Estudantes presentes neste Experimento?6]]) -> 20 | DX10: =_xlfn.XLOOKUP(OfficeForms.Table[[#This Row],[CHAVE LINK POLO]],'[1]Quadro Geral de Lotação'!$B:$B,'[1]Quadro Geral de Lotação'!$I:$I) -> Marla Maria Ferreira De Souza | DY10: =OfficeForms.Table[[#This Row],[Selecione a Ordem de Disciplina]] -> Ordem 1
A11: 11 | B11: 46073.68 | C11: 46073.682 | D11: maksllene.cavalcanti@tutorpratica.uniasselvi.com.br | E11: Maksllene Spessatto | I11: Herval D'Oeste/SC | L11: Ordem 1 | O11: Multidisciplinar II - Enfermagem e Instrumentação Cirúrgica | AG11: Administração de medicamento por Cateter Venoso Central + Monitorização hemodinâmica do paciente | AJ11: 46066 | AM11: 2 | AP11: https://uniasselvi01-my.sharepoint.com/personal/elienai_cesar_uniasselvi_com_br1/Documents/Aplicativos/Microsoft%20Forms/Question%C3%A1rio%20sem%20t%C3%ADtulo/Envio%20da%20Lista%20de%20Presen%C3%A7a/e780b836-baca-4cb8-8844-3647738bfd0d.pdf_Maksllene%20Spessatto.pdf | AS11: https://uniasselvi01-my.sharepoint.com/personal/elienai_cesar_uniasselvi_com_br1/Documents/Aplicativos/Microsoft%20Forms/Question%C3%A1rio%20sem%20t%C3%ADtulo/Envio%20do%20Portf%C3%B3lio%20em%20PDF/Portfolio%20(2)_Maksllene%20Spessatto.pdf; https://uniasselvi01-my.sharepoint.com/personal/elienai_cesar_uniasselvi_com_br1/Documents/Aplicativos/Microsoft%20Forms/Question%C3%A1rio%20sem%20t%C3%ADtulo/Envio%20do%20Portf%C3%B3lio%20em%20PDF/Portfolio%20(2)%202_Maksllene%20Spessatto.pdf | DS11: =_xlfn.XLOOKUP(OfficeForms.Table[[#This Row],[Selecione a Categoria do Laboratório desta atividade prática:]],Planilha1!A:A,Planilha1!B:B) -> EMF-ISN | DT11: =CONCATENATE(OfficeForms.Table[[#This Row],[Selecione seu Polo Laboratório de Atividades Presenciais:]],OfficeForms.Table[[#This Row],[CHAVE CONVERSÃO]]) -> Herval D'Oeste/SCEMF-ISN | DU11: =CONCATENATE(OfficeForms.Table[[#This Row],[Selecione quais Protocolos de Atividades Práticas foram realizados no laboratório:]],OfficeForms.Table[[#This Row],[Selecione quais Protocolos de Atividades Práticas foram realizados no laboratório:1]],OfficeForms.Table[[#This Row],[Selecione quais Protocolos de Atividades Práticas foram realizados no laboratório:2]],OfficeForms.Table[[#This Row],[Selecione quais Protocolos de Atividades Práticas foram realizados no laboratório:3]],OfficeForms.Table[[#This Row],[Selecione quais Protocolos de Atividades Práticas foram realizados no laboratório:4]],OfficeForms.Table[[#This Row],[Selecione quais Protocolos de Atividades Práticas foram realizados no laboratório:5]],OfficeForms.Table[[#This Row],[Selecione quais Protocolos de Atividades Práticas foram realizados no laboratório:6]]) -> Administração de medicamento por Cateter Venoso Central + Monitorização hemodinâmica do paciente | DV11: =SUM(OfficeForms.Table[[#This Row],[Data da aplicação do Protocolo de Prática:]],OfficeForms.Table[[#This Row],[Data da aplicação do Protocolo de Prática:1]],OfficeForms.Table[[#This Row],[Data da aplicação do Protocolo de Prática:2]],OfficeForms.Table[[#This Row],[Data da aplicação do Protocolo de Prática:3]],OfficeForms.Table[[#This Row],[Data da aplicação do Protocolo de Prática:4]],OfficeForms.Table[[#This Row],[Data da aplicação do Protocolo de Prática:5]],OfficeForms.Table[[#This Row],[Data da aplicação do Protocolo de Prática:6]]) -> 46066 | DW11: =SUM(OfficeForms.Table[[#This Row],[Quantos Estudantes presentes neste Experimento?]],OfficeForms.Table[[#This Row],[Quantos Estudantes presentes neste Experimento?1]],OfficeForms.Table[[#This Row],[Quantos Estudantes presentes neste Experimento?2]],OfficeForms.Table[[#This Row],[Quantos Estudantes presentes neste Experimento?3]],OfficeForms.Table[[#This Row],[Quantos Estudantes presentes neste Experimento?4]],OfficeForms.Table[[#This Row],[Quantos Estudantes presentes neste Experimento?5]],OfficeForms.Table[[#This Row],[Quantos Estudantes presentes neste Experimento?6]]) -> 2 | DX11: =_xlfn.XLOOKUP(OfficeForms.Table[[#This Row],[CHAVE LINK POLO]],'[1]Quadro Geral de Lotação'!$B:$B,'[1]Quadro Geral de Lotação'!$I:$I) -> Maksllene Ingrid De Souza Cavalcanti Spessatto | DY11: =OfficeForms.Table[[#This Row],[Selecione a Ordem de Disciplina]] -> Ordem 1
A12: 12 | B12: 46073.755 | C12: 46073.756 | D12: lucas.medeiros@tutorpratica.uniasselvi.com.br | E12: Lucas Medeiros | I12: Guarujá/SP | L12: Ordem 1 | O12: Multidisciplinar III - Biomedicina Estética, Fisioterapia, Terapia Ocupacional e Estética e Cosmética | AV12: Drenagem Linfática | AY12: 46071 | BB12: 1 | BE12: https://uniasselvi01-my.sharepoint.com/personal/elienai_cesar_uniasselvi_com_br1/Documents/Aplicativos/Microsoft%20Forms/Question%C3%A1rio%20sem%20t%C3%ADtulo/Envio%20da%20Lista%20de%20Presen%C3%A7a%201/IMG_0808_Lucas%20Medeiros.PNG | BH12: https://uniasselvi01-my.sharepoint.com/personal/elienai_cesar_uniasselvi_com_br1/Documents/Aplicativos/Microsoft%20Forms/Question%C3%A1rio%20sem%20t%C3%ADtulo/Envio%20do%20Portf%C3%B3lio%20em%20PDF%201/massagem%202_Lucas%20Medeiros.pdf | DS12: =_xlfn.XLOOKUP(OfficeForms.Table[[#This Row],[Selecione a Categoria do Laboratório desta atividade prática:]],Planilha1!A:A,Planilha1!B:B) -> BFI | DT12: =CONCATENATE(OfficeForms.Table[[#This Row],[Selecione seu Polo Laboratório de Atividades Presenciais:]],OfficeForms.Table[[#This Row],[CHAVE CONVERSÃO]]) -> Guarujá/SPBFI | DU12: =CONCATENATE(OfficeForms.Table[[#This Row],[Selecione quais Protocolos de Atividades Práticas foram realizados no laboratório:]],OfficeForms.Table[[#This Row],[Selecione quais Protocolos de Atividades Práticas foram realizados no laboratório:1]],OfficeForms.Table[[#This Row],[Selecione quais Protocolos de Atividades Práticas foram realizados no laboratório:2]],OfficeForms.Table[[#This Row],[Selecione quais Protocolos de Atividades Práticas foram realizados no laboratório:3]],OfficeForms.Table[[#This Row],[Selecione quais Protocolos de Atividades Práticas foram realizados no laboratório:4]],OfficeForms.Table[[#This Row],[Selecione quais Protocolos de Atividades Práticas foram realizados no laboratório:5]],OfficeForms.Table[[#This Row],[Selecione quais Protocolos de Atividades Práticas foram realizados no laboratório:6]]) -> Drenagem Linfática | DV12: =SUM(OfficeForms.Table[[#This Row],[Data da aplicação do Protocolo de Prática:]],OfficeForms.Table[[#This Row],[Data da aplicação do Protocolo de Prática:1]],OfficeForms.Table[[#This Row],[Data da aplicação do Protocolo de Prática:2]],OfficeForms.Table[[#This Row],[Data da aplicação do Protocolo de Prática:3]],OfficeForms.Table[[#This Row],[Data da aplicação do Protocolo de Prática:4]],OfficeForms.Table[[#This Row],[Data da aplicação do Protocolo de Prática:5]],OfficeForms.Table[[#This Row],[Data da aplicação do Protocolo de Prática:6]]) -> 46071 | DW12: =SUM(OfficeForms.Table[[#This Row],[Quantos Estudantes presentes neste Experimento?]],OfficeForms.Table[[#This Row],[Quantos Estudantes presentes neste Experimento?1]],OfficeForms.Table[[#This Row],[Quantos Estudantes presentes neste Experimento?2]],OfficeForms.Table[[#This Row],[Quantos Estudantes presentes neste Experimento?3]],OfficeForms.Table[[#This Row],[Quantos Estudantes presentes neste Experimento?4]],OfficeForms.Table[[#This Row],[Quantos Estudantes presentes neste Experimento?5]],OfficeForms.Table[[#This Row],[Quantos Estudantes presentes neste Experimento?6]]) -> 1 | DX12: =_xlfn.XLOOKUP(OfficeForms.Table[[#This Row],[CHAVE LINK POLO]],'[1]Quadro Geral de Lotação'!$B:$B,'[1]Quadro Geral de Lotação'!$I:$I) -> Lucas Soares De Medeiros | DY12: =OfficeForms.Table[[#This Row],[Selecione a Ordem de Disciplina]] -> Ordem 1
A13: 13 | B13: 46074.358 | C13: 46074.41 | D13: alina.silva@regentedepolo.uniasselvi.com.br | E13: Alina Silva | I13: Ananindeua/PA - Cidade Nova | L13: Ordem 1 | O13: Multidisciplinar II - Enfermagem e Instrumentação Cirúrgica | AG13: Trabalho de parto natural + Emergências obstétricas | AJ13: 46074 | AM13: 1 | AP13: https://uniasselvi01-my.sharepoint.com/personal/elienai_cesar_uniasselvi_com_br1/Documents/Aplicativos/Microsoft%20Forms/Question%C3%A1rio%20sem%20t%C3%ADtulo/Envio%20da%20Lista%20de%20Presen%C3%A7a/Freque%CC%82ncia%20dia%2021-02_Alina%20Silva.pdf | AS13: https://uniasselvi01-my.sharepoint.com/personal/elienai_cesar_uniasselvi_com_br1/Documents/Aplicativos/Microsoft%20Forms/Question%C3%A1rio%20sem%20t%C3%ADtulo/Envio%20do%20Portf%C3%B3lio%20em%20PDF/Trabalho%20de%20parto%20natural%20+%20Emerg%C3%AAncias%20Obst%C3%A9_Alina%20Silva.pdf | DS13: =_xlfn.XLOOKUP(OfficeForms.Table[[#This Row],[Selecione a Categoria do Laboratório desta atividade prática:]],Planilha1!A:A,Planilha1!B:B) -> EMF-ISN | DT13: =CONCATENATE(OfficeForms.Table[[#This Row],[Selecione seu Polo Laboratório de Atividades Presenciais:]],OfficeForms.Table[[#This Row],[CHAVE CONVERSÃO]]) -> Ananindeua/PA - Cidade NovaEMF-ISN | DU13: =CONCATENATE(OfficeForms.Table[[#This Row],[Selecione quais Protocolos de Atividades Práticas foram realizados no laboratório:]],OfficeForms.Table[[#This Row],[Selecione quais Protocolos de Atividades Práticas foram realizados no laboratório:1]],OfficeForms.Table[[#This Row],[Selecione quais Protocolos de Atividades Práticas foram realizados no laboratório:2]],OfficeForms.Table[[#This Row],[Selecione quais Protocolos de Atividades Práticas foram realizados no laboratório:3]],OfficeForms.Table[[#This Row],[Selecione quais Protocolos de Atividades Práticas foram realizados no laboratório:4]],OfficeForms.Table[[#This Row],[Selecione quais Protocolos de Atividades Práticas foram realizados no laboratório:5]],OfficeForms.Table[[#This Row],[Selecione quais Protocolos de Atividades Práticas foram realizados no laboratório:6]]) -> Trabalho de parto natural + Emergências obstétricas | DV13: =SUM(OfficeForms.Table[[#This Row],[Data da aplicação do Protocolo de Prática:]],OfficeForms.Table[[#This Row],[Data da aplicação do Protocolo de Prática:1]],OfficeForms.Table[[#This Row],[Data da aplicação do Protocolo de Prática:2]],OfficeForms.Table[[#This Row],[Data da aplicação do Protocolo de Prática:3]],OfficeForms.Table[[#This Row],[Data da aplicação do Protocolo de Prática:4]],OfficeForms.Table[[#This Row],[Data da aplicação do Protocolo de Prática:5]],OfficeForms.Table[[#This Row],[Data da aplicação do Protocolo de Prática:6]]) -> 46074 | DW13: =SUM(OfficeForms.Table[[#This Row],[Quantos Estudantes presentes neste Experimento?]],OfficeForms.Table[[#This Row],[Quantos Estudantes presentes neste Experimento?1]],OfficeForms.Table[[#This Row],[Quantos Estudantes presentes neste Experimento?2]],OfficeForms.Table[[#This Row],[Quantos Estudantes presentes neste Experimento?3]],OfficeForms.Table[[#This Row],[Quantos Estudantes presentes neste Experimento?4]],OfficeForms.Table[[#This Row],[Quantos Estudantes presentes neste Experimento?5]],OfficeForms.Table[[#This Row],[Quantos Estudantes presentes neste Experimento?6]]) -> 1 | DX13: =_xlfn.XLOOKUP(OfficeForms.Table[[#This Row],[CHAVE LINK POLO]],'[1]Quadro Geral de Lotação'!$B:$B,'[1]Quadro Geral de Lotação'!$I:$I) -> Alina Dariane Freitas Da Silva | DY13: =OfficeForms.Table[[#This Row],[Selecione a Ordem de Disciplina]] -> Ordem 1
A14: 14 | B14: 46074.472 | C14: 46074.474 | D14: vitor.pinheiro@tutorpratica.uniasselvi.com.br | E14: Vitor Pinheiro | I14: Alagoinhas/BA | L14: Ordem 1 | O14: Química e Física - Agronomia | DD14: Métodos de determinação da fertilidade do solo | DG14: 46074 | DJ14: 1 | DM14: https://uniasselvi01-my.sharepoint.com/personal/elienai_cesar_uniasselvi_com_br1/Documents/Aplicativos/Microsoft%20Forms/Question%C3%A1rio%20sem%20t%C3%ADtulo/Envio%20da%20Lista%20de%20Presen%C3%A7a%205/WhatsApp%20Image%202026-02-21%20at%2011.21.51%20AM_Vitor%20Pinheiro.jpeg | DP14: https://uniasselvi01-my.sharepoint.com/personal/elienai_cesar_uniasselvi_com_br1/_layouts/15/Doc.aspx?sourcedoc=%7BF12AC8C2-45E5-4775-92E0-C3AB5053814E%7D&file=Portf%C3%B3lio%20das%20Atividades%20Pr%C3%A1ticas%20-%20Fertilida_Vitor%20Pinheiro.docx&action=default&mobileredirect=true | DS14: =_xlfn.XLOOKUP(OfficeForms.Table[[#This Row],[Selecione a Categoria do Laboratório desta atividade prática:]],Planilha1!A:A,Planilha1!B:B) -> AGM | DT14: =CONCATENATE(OfficeForms.Table[[#This Row],[Selecione seu Polo Laboratório de Atividades Presenciais:]],OfficeForms.Table[[#This Row],[CHAVE CONVERSÃO]]) -> Alagoinhas/BAAGM | DU14: =CONCATENATE(OfficeForms.Table[[#This Row],[Selecione quais Protocolos de Atividades Práticas foram realizados no laboratório:]],OfficeForms.Table[[#This Row],[Selecione quais Protocolos de Atividades Práticas foram realizados no laboratório:1]],OfficeForms.Table[[#This Row],[Selecione quais Protocolos de Atividades Práticas foram realizados no laboratório:2]],OfficeForms.Table[[#This Row],[Selecione quais Protocolos de Atividades Práticas foram realizados no laboratório:3]],OfficeForms.Table[[#This Row],[Selecione quais Protocolos de Atividades Práticas foram realizados no laboratório:4]],OfficeForms.Table[[#This Row],[Selecione quais Protocolos de Atividades Práticas foram realizados no laboratório:5]],OfficeForms.Table[[#This Row],[Selecione quais Protocolos de Atividades Práticas foram realizados no laboratório:6]]) -> Métodos de determinação da fertilidade do solo | DV14: =SUM(OfficeForms.Table[[#This Row],[Data da aplicação do Protocolo de Prática:]],OfficeForms.Table[[#This Row],[Data da aplicação do Protocolo de Prática:1]],OfficeForms.Table[[#This Row],[Data da aplicação do Protocolo de Prática:2]],OfficeForms.Table[[#This Row],[Data da aplicação do Protocolo de Prática:3]],OfficeForms.Table[[#This Row],[Data da aplicação do Protocolo de Prática:4]],OfficeForms.Table[[#This Row],[Data da aplicação do Protocolo de Prática:5]],OfficeForms.Table[[#This Row],[Data da aplicação do Protocolo de Prática:6]]) -> 46074 | DW14: =SUM(OfficeForms.Table[[#This Row],[Quantos Estudantes presentes neste Experimento?]],OfficeForms.Table[[#This Row],[Quantos Estudantes presentes neste Experimento?1]],OfficeForms.Table[[#This Row],[Quantos Estudantes presentes neste Experimento?2]],OfficeForms.Table[[#This Row],[Quantos Estudantes presentes neste Experimento?3]],OfficeForms.Table[[#This Row],[Quantos Estudantes presentes neste Experimento?4]],OfficeForms.Table[[#This Row],[Quantos Estudantes presentes neste Experimento?5]],OfficeForms.Table[[#This Row],[Quantos Estudantes presentes neste Experimento?6]]) -> 1 | DX14: =_xlfn.XLOOKUP(OfficeForms.Table[[#This Row],[CHAVE LINK POLO]],'[1]Quadro Geral de Lotação'!$B:$B,'[1]Quadro Geral de Lotação'!$I:$I) -> Vitor Batista Pinheiro | DY14: =OfficeForms.Table[[#This Row],[Selecione a Ordem de Disciplina]] -> Ordem 1
A15: 15 | B15: 46074.567 | C15: 46074.586 | D15: quezia.silva@regentedepolo.uniasselvi.com.br | E15: Quezia Silva | I15: Rolim de Moura/RO | L15: Ordem 1 | O15: Multidisciplinar II - Enfermagem e Instrumentação Cirúrgica | AG15: Aspiração de vias aéreas (com e sem TOT) | AJ15: 46072 | AM15: 4 | AP15: https://uniasselvi01-my.sharepoint.com/personal/elienai_cesar_uniasselvi_com_br1/_layouts/15/Doc.aspx?sourcedoc=%7B2DD41765-8283-455F-A963-228BCA33EE95%7D&file=_Lista%20de%20Presen%C3%A7a%20das%20Pr%C3%A1ticas%2019.02.26_Quezia%20Silva.docx&action=default&mobileredirect=true | AS15: https://uniasselvi01-my.sharepoint.com/personal/elienai_cesar_uniasselvi_com_br1/_layouts/15/Doc.aspx?sourcedoc=%7B78B147B4-AB01-42B2-8EDE-2DF5436F4BD4%7D&file=portifolio%20Quezia%20vias%20aeria%2019.02.26_Quezia%20Silva.docx&action=default&mobileredirect=true | DS15: =_xlfn.XLOOKUP(OfficeForms.Table[[#This Row],[Selecione a Categoria do Laboratório desta atividade prática:]],Planilha1!A:A,Planilha1!B:B) -> EMF-ISN | DT15: =CONCATENATE(OfficeForms.Table[[#This Row],[Selecione seu Polo Laboratório de Atividades Presenciais:]],OfficeForms.Table[[#This Row],[CHAVE CONVERSÃO]]) -> Rolim de Moura/ROEMF-ISN | DU15: =CONCATENATE(OfficeForms.Table[[#This Row],[Selecione quais Protocolos de Atividades Práticas foram realizados no laboratório:]],OfficeForms.Table[[#This Row],[Selecione quais Protocolos de Atividades Práticas foram realizados no laboratório:1]],OfficeForms.Table[[#This Row],[Selecione quais Protocolos de Atividades Práticas foram realizados no laboratório:2]],OfficeForms.Table[[#This Row],[Selecione quais Protocolos de Atividades Práticas foram realizados no laboratório:3]],OfficeForms.Table[[#This Row],[Selecione quais Protocolos de Atividades Práticas foram realizados no laboratório:4]],OfficeForms.Table[[#This Row],[Selecione quais Protocolos de Atividades Práticas foram realizados no laboratório:5]],OfficeForms.Table[[#This Row],[Selecione quais Protocolos de Atividades Práticas foram realizados no laboratório:6]]) -> Aspiração de vias aéreas (com e sem TOT) | DV15: =SUM(OfficeForms.Table[[#This Row],[Data da aplicação do Protocolo de Prática:]],OfficeForms.Table[[#This Row],[Data da aplicação do Protocolo de Prática:1]],OfficeForms.Table[[#This Row],[Data da aplicação do Protocolo de Prática:2]],OfficeForms.Table[[#This Row],[Data da aplicação do Protocolo de Prática:3]],OfficeForms.Table[[#This Row],[Data da aplicação do Protocolo de Prática:4]],OfficeForms.Table[[#This Row],[Data da aplicação do Protocolo de Prática:5]],OfficeForms.Table[[#This Row],[Data da aplicação do Protocolo de Prática:6]]) -> 46072 | DW15: =SUM(OfficeForms.Table[[#This Row],[Quantos Estudantes presentes neste Experimento?]],OfficeForms.Table[[#This Row],[Quantos Estudantes presentes neste Experimento?1]],OfficeForms.Table[[#This Row],[Quantos Estudantes presentes neste Experimento?2]],OfficeForms.Table[[#This Row],[Quantos Estudantes presentes neste Experimento?3]],OfficeForms.Table[[#This Row],[Quantos Estudantes presentes neste Experimento?4]],OfficeForms.Table[[#This Row],[Quantos Estudantes presentes neste Experimento?5]],OfficeForms.Table[[#This Row],[Quantos Estudantes presentes neste Experimento?6]]) -> 4 | DX15: =_xlfn.XLOOKUP(OfficeForms.Table[[#This Row],[CHAVE LINK POLO]],'[1]Quadro Geral de Lotação'!$B:$B,'[1]Quadro Geral de Lotação'!$I:$I) -> Quezia Da Silva Dos Anjos Da Silva | DY15: =OfficeForms.Table[[#This Row],[Selecione a Ordem de Disciplina]] -> Ordem 1
